Workbook

Sheet Cover
B2: CLOZR BUSINESS SUITE
B3: UAT & System Test Checklist — Production Release Validation · v4 · Backend baseline: Clozr-Version02
B5: TEST RUN DETAILS
B6: Tester name | C6: Cijo George | E6: Browser & version | F6: e.g. Chrome 128
B7: Tester role | C7: Backend dev | E7: Device / OS | F7: windows
B8: Environment / URL | C8: Staging - dev.clozr.tech | E8: Test start (date & time) | F8: 46258
B9: App build / version | C9: release-2026-08-21 | E9: Test end (date & time) | F9: 46258.75
B11: RESULTS SUMMARY (fills in automatically as you mark each sheet)
B12: Module (sheet) | C12: Total | D12: Pass | E12: Fail | F12: Blocked | G12: Not Run | H12: % Passed
B13: 1. Onboarding & Login | C13: =COUNT('1. Onboarding & Login'!A2:A38) -> 31 | D13: =COUNTIF('1. Onboarding & Login'!D2:D38,"Pass") -> 0 | E13: =COUNTIF('1. Onboarding & Login'!D2:D38,"Fail") -> 0 | F13: =COUNTIF('1. Onboarding & Login'!D2:D38,"Blocked") -> 0 | G13: =C13-D13-E13-F13-COUNTIF('1. Onboarding & Login'!D2:D38,"N/A") -> 31 | H13: =IFERROR(D13/C13,0) -> 0
B14: 2. Admin - Users & Teams | C14: =COUNT('2. Admin - Users & Teams'!A2:A29) -> 23 | D14: =COUNTIF('2. Admin - Users & Teams'!D2:D29,"Pass") -> 0 | E14: =COUNTIF('2. Admin - Users & Teams'!D2:D29,"Fail") -> 0 | F14: =COUNTIF('2. Admin - Users & Teams'!D2:D29,"Blocked") -> 0 | G14: =C14-D14-E14-F14-COUNTIF('2. Admin - Users & Teams'!D2:D29,"N/A") -> 23 | H14: =IFERROR(D14/C14,0) -> 0
B15: 3. Roles & Scoping | C15: =COUNT('3. Roles & Scoping'!A2:A48) -> 37 | D15: =COUNTIF('3. Roles & Scoping'!D2:D48,"Pass") -> 0 | E15: =COUNTIF('3. Roles & Scoping'!D2:D48,"Fail") -> 0 | F15: =COUNTIF('3. Roles & Scoping'!D2:D48,"Blocked") -> 0 | G15: =C15-D15-E15-F15-COUNTIF('3. Roles & Scoping'!D2:D48,"N/A") -> 37 | H15: =IFERROR(D15/C15,0) -> 0
B16: 4. Editing & Audit Log | C16: =COUNT('4. Editing & Audit Log'!A2:A21) -> 16 | D16: =COUNTIF('4. Editing & Audit Log'!D2:D21,"Pass") -> 0 | E16: =COUNTIF('4. Editing & Audit Log'!D2:D21,"Fail") -> 0 | F16: =COUNTIF('4. Editing & Audit Log'!D2:D21,"Blocked") -> 0 | G16: =C16-D16-E16-F16-COUNTIF('4. Editing & Audit Log'!D2:D21,"N/A") -> 16 | H16: =IFERROR(D16/C16,0) -> 0
B17: 5. Filters, Columns & Views | C17: =COUNT('5. Filters, Columns & Views'!A2:A46) -> 37 | D17: =COUNTIF('5. Filters, Columns & Views'!D2:D46,"Pass") -> 0 | E17: =COUNTIF('5. Filters, Columns & Views'!D2:D46,"Fail") -> 0 | F17: =COUNTIF('5. Filters, Columns & Views'!D2:D46,"Blocked") -> 0 | G17: =C17-D17-E17-F17-COUNTIF('5. Filters, Columns & Views'!D2:D46,"N/A") -> 37 | H17: =IFERROR(D17/C17,0) -> 0
B18: 6. CRM - Leads | C18: =COUNT('6. CRM - Leads'!A2:A63) -> 52 | D18: =COUNTIF('6. CRM - Leads'!D2:D63,"Pass") -> 0 | E18: =COUNTIF('6. CRM - Leads'!D2:D63,"Fail") -> 0 | F18: =COUNTIF('6. CRM - Leads'!D2:D63,"Blocked") -> 0 | G18: =C18-D18-E18-F18-COUNTIF('6. CRM - Leads'!D2:D63,"N/A") -> 52 | H18: =IFERROR(D18/C18,0) -> 0
B19: 7. Capture & Routing | C19: =COUNT('7. Capture & Routing'!A2:A39) -> 33 | D19: =COUNTIF('7. Capture & Routing'!D2:D39,"Pass") -> 0 | E19: =COUNTIF('7. Capture & Routing'!D2:D39,"Fail") -> 0 | F19: =COUNTIF('7. Capture & Routing'!D2:D39,"Blocked") -> 0 | G19: =C19-D19-E19-F19-COUNTIF('7. Capture & Routing'!D2:D39,"N/A") -> 33 | H19: =IFERROR(D19/C19,0) -> 0
B20: 8. Money Path (Quote-Pay) | C20: =COUNT('8. Money Path (Quote-Pay)'!A2:A56) -> 42 | D20: =COUNTIF('8. Money Path (Quote-Pay)'!D2:D56,"Pass") -> 0 | E20: =COUNTIF('8. Money Path (Quote-Pay)'!D2:D56,"Fail") -> 0 | F20: =COUNTIF('8. Money Path (Quote-Pay)'!D2:D56,"Blocked") -> 0 | G20: =C20-D20-E20-F20-COUNTIF('8. Money Path (Quote-Pay)'!D2:D56,"N/A") -> 42 | H20: =IFERROR(D20/C20,0) -> 0
B21: 9. CRM - Records | C21: =COUNT('9. CRM - Records'!A2:A46) -> 37 | D21: =COUNTIF('9. CRM - Records'!D2:D46,"Pass") -> 0 | E21: =COUNTIF('9. CRM - Records'!D2:D46,"Fail") -> 0 | F21: =COUNTIF('9. CRM - Records'!D2:D46,"Blocked") -> 0 | G21: =C21-D21-E21-F21-COUNTIF('9. CRM - Records'!D2:D46,"N/A") -> 37 | H21: =IFERROR(D21/C21,0) -> 0
B22: 10. Project | C22: =COUNT('10. Project'!A2:A40) -> 31 | D22: =COUNTIF('10. Project'!D2:D40,"Pass") -> 17 | E22: =COUNTIF('10. Project'!D2:D40,"Fail") -> 5 | F22: =COUNTIF('10. Project'!D2:D40,"Blocked") -> 7 | G22: =C22-D22-E22-F22-COUNTIF('10. Project'!D2:D40,"N/A") -> 1 | H22: =IFERROR(D22/C22,0) -> 0.5483871
B23: 11. Helpdesk | C23: =COUNT('11. Helpdesk'!A2:A28) -> 22 | D23: =COUNTIF('11. Helpdesk'!D2:D28,"Pass") -> 10 | E23: =COUNTIF('11. Helpdesk'!D2:D28,"Fail") -> 2 | F23: =COUNTIF('11. Helpdesk'!D2:D28,"Blocked") -> 7 | G23: =C23-D23-E23-F23-COUNTIF('11. Helpdesk'!D2:D28,"N/A") -> 2 | H23: =IFERROR(D23/C23,0) -> 0.45454545
B24: 12. LMS (Training) | C24: =COUNT('12. LMS (Training)'!A2:A34) -> 26 | D24: =COUNTIF('12. LMS (Training)'!D2:D34,"Pass") -> 0 | E24: =COUNTIF('12. LMS (Training)'!D2:D34,"Fail") -> 0 | F24: =COUNTIF('12. LMS (Training)'!D2:D34,"Blocked") -> 0 | G24: =C24-D24-E24-F24-COUNTIF('12. LMS (Training)'!D2:D34,"N/A") -> 26 | H24: =IFERROR(D24/C24,0) -> 0
B25: 13. Automations | C25: =COUNT('13. Automations'!A2:A48) -> 38 | D25: =COUNTIF('13. Automations'!D2:D48,"Pass") -> 25 | E25: =COUNTIF('13. Automations'!D2:D48,"Fail") -> 2 | F25: =COUNTIF('13. Automations'!D2:D48,"Blocked") -> 3 | G25: =C25-D25-E25-F25-COUNTIF('13. Automations'!D2:D48,"N/A") -> 7 | H25: =IFERROR(D25/C25,0) -> 0.65789474
B26: 14. Goals & Rewards | C26: =COUNT('14. Goals & Rewards'!A2:A58) -> 45 | D26: =COUNTIF('14. Goals & Rewards'!D2:D58,"Pass") -> 7 | E26: =COUNTIF('14. Goals & Rewards'!D2:D58,"Fail") -> 0 | F26: =COUNTIF('14. Goals & Rewards'!D2:D58,"Blocked") -> 1 | G26: =C26-D26-E26-F26-COUNTIF('14. Goals & Rewards'!D2:D58,"N/A") -> 37 | H26: =IFERROR(D26/C26,0) -> 0.15555556
B27: 15. Billing | C27: =COUNT('15. Billing'!A2:A22) -> 17 | D27: =COUNTIF('15. Billing'!D2:D22,"Pass") -> 12 | E27: =COUNTIF('15. Billing'!D2:D22,"Fail") -> 3 | F27: =COUNTIF('15. Billing'!D2:D22,"Blocked") -> 1 | G27: =C27-D27-E27-F27-COUNTIF('15. Billing'!D2:D22,"N/A") -> 1 | H27: =IFERROR(D27/C27,0) -> 0.70588235
B28: 16. Communications | C28: =COUNT('16. Communications'!A2:A34) -> 27 | D28: =COUNTIF('16. Communications'!D2:D34,"Pass") -> 9 | E28: =COUNTIF('16. Communications'!D2:D34,"Fail") -> 1 | F28: =COUNTIF('16. Communications'!D2:D34,"Blocked") -> 10 | G28: =C28-D28-E28-F28-COUNTIF('16. Communications'!D2:D34,"N/A") -> 6 | H28: =IFERROR(D28/C28,0) -> 0.33333333
B29: 17. Reports | C29: =COUNT('17. Reports'!A2:A18) -> 14 | D29: =COUNTIF('17. Reports'!D2:D18,"Pass") -> 5 | E29: =COUNTIF('17. Reports'!D2:D18,"Fail") -> 2 | F29: =COUNTIF('17. Reports'!D2:D18,"Blocked") -> 4 | G29: =C29-D29-E29-F29-COUNTIF('17. Reports'!D2:D18,"N/A") -> 3 | H29: =IFERROR(D29/C29,0) -> 0.35714286
B30: 18. Misc (Cross-Module) | C30: =COUNT('18. Misc (Cross-Module)'!A2:A52) -> 38 | D30: =COUNTIF('18. Misc (Cross-Module)'!D2:D52,"Pass") -> 0 | E30: =COUNTIF('18. Misc (Cross-Module)'!D2:D52,"Fail") -> 0 | F30: =COUNTIF('18. Misc (Cross-Module)'!D2:D52,"Blocked") -> 0 | G30: =C30-D30-E30-F30-COUNTIF('18. Misc (Cross-Module)'!D2:D52,"N/A") -> 38 | H30: =IFERROR(D30/C30,0) -> 0
B31: GRAND TOTAL | C31: =SUM(C13:C30) -> 566 | D31: =SUM(D13:D30) -> 85 | E31: =SUM(E13:E30) -> 15 | F31: =SUM(F13:F30) -> 33 | G31: =SUM(G13:G30) -> 429 | H31: =IFERROR(D31/C31,0) -> 0.15017668
B33: Overall release verdict | C33: Go / No-Go
B34: Signed off by / date
B36: Notes / blockers:

Sheet How to Use
B2: How to use this checklist
B3: This workbook checks that every part of the Clozr Business Suite works before it goes live. You do not need any technical knowledge. Just do what each row says and mark what happened.
B4: The tabs at the bottom
B5: • Cover — fill in your name and details at the top. The results table fills in by itself as you work.
B6: • How to Use — this page.
B7: • One tab per area of the app (Onboarding, Admin, CRM, Project, Helpdesk, LMS, Billing, Communications, Reports). The last tab, 'Misc', covers things that affect the whole app.
B8: Each test row has five columns
B9: • Sl No — the row number.
B10: • Action — what YOU should do in the app.
B11: • Expected Outcome — what SHOULD happen if the app is working correctly.
B12: • Result — click the cell and pick Pass, Fail, Blocked or N/A from the drop-down.
B13: • Remarks — write anything you noticed: what went wrong, a screenshot name, or a question.
... B38: • You should never see a raw technical error, a blank white page, or a loader that never stops. If you do, note it as a Fail with the screen name.

Sheet 1. Onboarding & Login
A1: Sl No | B1: Action | C1: Expected Outcome | D1: Result | E1: Remarks
A2: A. SIGN UP A NEW COMPANY (WORKSPACE)
A3: 1 | B3: Open the sign-up page and register a new company with a valid name, a web address (subdomain), your name, e-mail and a strong password. | C3: The company is created. You are told to check your e-mail, or you are taken into the app.
A4: 2 | B4: Try to sign up again using the SAME company web address (subdomain). | C4: Blocked with a clear 'web address already taken' message.
A5: 3 | B5: Try to sign up with the SAME company name as an existing company. | C5: Blocked with a clear 'company name already exists' message.
A6: 4 | B6: Try to sign up with a badly-formed e-mail such as 'john@' or 'john.com'. | C6: Blocked; e-mail marked not valid. The company is NOT created.
A7: 5 | B7: Try to sign up with a very weak password such as '123'. | C7: Blocked; the password rules are shown (length, letters, numbers, special sign).
A8: 6 | B8: Leave the company name blank and press Sign up. | C8: Blocked; company name marked as required.
A9: 7 | B9: Type a company name of about 300 letters and sign up. | C9: The app trims sensibly or shows a clear limit message; it does not crash or show a raw error.
A10: 8 | B10: Paste <script>alert(1)</script> into the company name and sign up. | C10: The text is stored as plain words; no pop-up ever appears where the name is later shown.
A11: B. ACTIVATE THE ACCOUNT (E-MAIL LINK)
A12: 9 | B12: Open the activation e-mail, click the link and set a password. | C12: The password is accepted and the account becomes active.
A13: 10 | B13: Click the SAME activation link again after the account is already active. | C13: Handled gracefully with a clear message; no broken page or raw error.
A14: 11 | B14: Wait until the activation link is expired, click it, then use 'resend activation'. | C14: The old link is refused; a fresh activation e-mail is sent.
A15: C. LOG IN
A16: 12 | B16: Log in with the correct e-mail and password. | C16: Signed in; you land on the Dashboard.
A17: 13 | B17: Log in with the correct e-mail but a WRONG password. | C17: Refused with a clear message that does NOT reveal whether the e-mail exists.
A18: 14 | B18: Leave both e-mail and password blank and press Log in. | C18: Both boxes marked required; no login attempt is made.
A19: 15 | B19: Enter a wrong password 5 times in a row for the same e-mail. | C19: After the set number of tries the account is locked with a clear message.
A20: 16 | B20: While locked, try to log in with the CORRECT password. | C20: Still refused because the account is locked.
A21: 17 | B21: Wait for the lock time to pass (or ask admin to reset), then log in correctly. | C21: Login works again.
A22: 18 | B22: After being locked and then logging in once correctly, fail again and count the tries. | C22: The failed-attempt count was reset by the good login; a fresh set of tries is allowed.
A23: D. TWO-STEP LOGIN (2FA) — IF TURNED ON
A24: 19 | B24: Turn on two-step login in security settings and complete setup. | C24: Two-step login is set up and confirmed.
A25: 20 | B25: Log out and log in again with two-step login on. | C25: After the password, the app asks for the second code before letting you in.
A26: 21 | B26: On the second-step screen, type a wrong code. | C26: The code is refused; you are not let in.
A27: 22 | B27: Turn off two-step login. | C27: The next login needs only the password.
A28: E. STAYING LOGGED IN / SESSIONS
A29: 23 | B29: Stay active for more than 30 minutes without logging out. | C29: You are not thrown out mid-work; the session stays alive quietly.
A30: 24 | B30: Leave the app idle for the inactivity period set in security policy, then return. | C30: The app behaves per the inactivity rule; it does not silently keep an unsafe session.
A31: 25 | B31: Open Settings > Security > Sessions. | C31: Your current sign-in is listed with device/browser and last-active time.
A32: 26 | B32: Log in from a second browser/device with the same account. | C32: The second session appears; both work per the max-sessions rule (default 5).
A33: 27 | B33: Click Log out, then press browser Back and try to reach an inside page. | C33: You are sent to the login page, not shown old page content.
A34: F. FORGOT PASSWORD
A35: 28 | B35: Use 'Forgot password', enter your e-mail and submit. | C35: You are told a reset link has been sent (whether or not the e-mail exists).
A36: 29 | B36: Open the reset e-mail, click the link and set a new password. | C36: The new password is accepted; you can log in with it.
A37: 30 | B37: Try the same reset link again, or after it has expired. | C37: Refused with a clear message; it cannot be reused.
A38: 31 | B38: Request a reset for an e-mail that does NOT exist. | C38: The same neutral 'link sent' message appears; it does not reveal the e-mail is unknown.

Sheet 2. Admin - Users & Teams
A1: Sl No | B1: Action | C1: Expected Outcome | D1: Result | E1: Remarks
A2: A. COMPANY PROFILE & BRANDING
A3: 1 | B3: Fill in the company profile: logo, brand colours, address, time zone, date format, first day of week, currency. | C3: All values save and show correctly on re-open.
A4: 2 | B4: Change the company currency (INR / USD / EUR / AED) and save. | C4: The new currency is used where money is shown for new records.
A5: 3 | B5: Set business hours and turn on 'restrict to business hours'. | C5: The setting saves (it later affects lead auto-assignment timing).
A6: 4 | B6: Upload a company logo larger than 10 MB. | C6: Refused with a clear size message; no hang or crash.
A7: 5 | B7: Upload a non-image file renamed to .png as the logo. | C7: Rejected as an invalid image with a clear message.
A8: 6 | B8: Set the financial year start month and first day of week, then open a dashboard with a date range. | C8: Date ranges and week grouping follow the company settings.
A9: B. INVITE & MANAGE USERS
A10: 7 | B10: Add a new user with name, e-mail and role. | C10: The user is created and an activation e-mail is sent.
A11: 8 | B11: Try to add a user with an e-mail ALREADY used by any user in the system. | C11: Blocked; e-mail already in use.
A12: 9 | B12: Open the new user's detail page. | C12: It shows the user's information, role and status.
A13: 10 | B13: Deactivate a user, then try to log in as them. | C13: Login is refused; the user is inactive.
A14: 11 | B14: Re-activate the user and log in. | C14: The user can log in once active.
A15: 12 | B15: Mark a user as non-billable (service account) if available. | C15: Saved as non-billable; does not add to the paid seat count.
A16: 13 | B16: Deactivate a user who OWNS leads and customers, then look at those records. | C16: The records are not deleted; ownership is cleared or handled cleanly, not broken.
A17: C. TEAMS
A18: 14 | B18: Create a team with a manager and several members. | C18: The team saves with its manager and members.
A19: 15 | B19: Try to create a second team with the SAME name. | C19: Blocked; team name already exists.
A20: 16 | B20: Remove a member from a team and add a different one. | C20: Membership updates correctly.
A21: 17 | B21: Assign a lead to a TEAM (not a person). | C21: The lead shows the assigned team.
A22: D. REPORTING HIERARCHY
A23: 18 | B23: Set a manager for a user from the hierarchy screen. | C23: Saved and shown in the hierarchy tree.
A24: 19 | B24: Open the hierarchy tree view. | C24: The tree shows who reports to whom.
A25: 20 | B25: Try to give a user two active managers at the same time. | C25: The app keeps only one active manager; the old one is replaced cleanly.
A26: 21 | B26: Build a chain: A manages B, B manages C. View subordinates for A. | C26: A's subordinates include BOTH B and C (the whole chain, not just direct reports).
A27: E. AUDIT TRAIL
A28: 22 | B28: Create a lead, edit a user and change a role, then open the Audit Log. | C28: The three actions appear with who did them and when.
A29: 23 | B29: Export the audit log (if your role allows). | C29: A file downloads with the audit entries.

Sheet 3. Roles & Scoping
A1: Sl No | B1: Action | C1: Expected Outcome | D1: Result | E1: Remarks
A2: A. BUILD ROLES (module permissions = WHAT you can do)
A3: 1 | B3: Create a role and turn ON only View and Export for Leads (Create/Edit/Delete/Import/Approve OFF). | C3: The choices save exactly as set.
A4: 2 | B4: Assign that role to test user U1, log in as U1 and open Leads. | C4: U1 can see and export leads, but Add / Edit / Delete are hidden or blocked.
A5: 3 | B5: As U1, open the New Lead page by typing its web address directly. | C5: Blocked with a clear 'no access' message (server-enforced, not just a hidden button).
A6: 4 | B6: As U1, find the delete action's address and try to trigger a delete directly. | C6: The delete is refused on the server too, not only hidden in the screen.
A7: 5 | B7: Turn ON Import for Leads for U1's role and reload; try to import. | C7: Import is now allowed for U1.
A8: 6 | B8: Give a role Approve on Leads but NOT Edit; check lead conversion approval. | C8: The Approve permission works for approvals even though Edit is off.
A9: 7 | B9: Create a user with NO role and log in. | C9: They see almost no menu items and cannot open the gated screens.
A10: B. SCOPE = OWNED (which records you can see)
A11: 8 | B11: SETUP: Create role 'Owned-Only' with Lead visibility = Owned records. Assign to U2, who is NOT in any team. Create Lead-A owned by U2 and Lead-B owned by someone else. Log in as U2. | C11: Setup ready.
A12: 9 | B12: As U2, open the Leads list. | C12: U2 sees Lead-A (their own) but NOT Lead-B.
A13: 10 | B13: As U2, open Lead-B directly by its web address. | C13: Blocked — U2 cannot open a lead they do not own.
A14: 11 | B14: As U2, edit Lead-A. | C14: Allowed — the owner can always edit their own record.
A15: 12 | B15: Assign Lead-B to U2 as an ASSIGNEE (keep a different owner). As U2, open the list. | C15: Lead-B now also appears for U2 — 'owned' scope also includes records assigned to the user.
A16: C. SCOPE = OWNED + TEAM OVERLAY (important hidden behaviour)
A17: 13 | B17: SETUP: Put U2 into a Team with teammate U3. U3 owns Lead-C. Keep U2's role at 'Owned records'. Log in as U2. | C17: Setup ready.
A18: 14 | B18: As U2 (owned scope) open the Leads list and look for U3's Lead-C. | C18: Lead-C IS visible to U2 — being on a team quietly adds teammates' records even under 'owned' scope. Confirm this is intended.
A19: 15 | B19: Remove U2 from the team and reload the list (allow a few minutes for permissions to refresh). | C19: Lead-C disappears for U2 once they are no longer a teammate.
A20: D. SCOPE = ASSIGNED / TEAM / HIERARCHY / ALL
A21: 16 | B21: SETUP: Create role 'Assigned-Only' (Lead = Assigned records), assign to U4 not in a team. Make U4 an assignee on Lead-D only. Log in as U4. | C21: Setup ready.
A22: 17 | B22: As U4 open the Leads list. | C22: U4 sees only leads they are an assignee on (Lead-D), not ones merely owned by others.
A23: 18 | B23: SETUP: Create role 'Team-Scope' (Lead = Team records), assign to U5 who shares a team with U6. U6 owns Lead-E. Log in as U5. | C23: Setup ready.
A24: 19 | B24: As U5 open the Leads list. | C24: U5 sees leads owned/assigned by any teammate (including U6's Lead-E).
A25: 20 | B25: SETUP: Create role 'Hierarchy-Scope' (Lead = Hierarchy records) for manager M who manages S1 who manages S2. Log in as M. | C25: Setup ready.
A26: 21 | B26: As M open the Leads list with M, S1 and S2 each owning a lead. | C26: M sees M's, S1's AND S2's leads (own + everyone below, all the way down).
A27: 22 | B27: SETUP: Create role 'All-Scope' (Lead = All records) for U7. Log in as U7. | C27: Setup ready.
A28: 23 | B28: As U7 open the Leads list. | C28: U7 sees every lead in the company.
A29: E. SCOPE = FILTERED (custom condition)
A30: 24 | B30: SETUP: Create role 'Filtered' with Lead = Filtered records and a condition (e.g. only a chosen source or territory). Assign to U8. Create leads matching and not matching the condition. | C30: Setup ready.
A31: 25 | B31: As U8 open the Leads list. | C31: U8 sees only the leads that match the saved filter condition, and no others.
A32: F. WHEN A USER HAS TWO ROLES (precedence)
A33: 26 | B33: Give one user BOTH an 'Owned records' role and an 'All records' role for Leads. Log in as them. | C33: The wider scope wins — they see ALL leads (precedence order: All > Hierarchy > Team > Owned > Assigned > Filtered).
A34: 27 | B34: Give a user a 'Team' role and a 'Hierarchy' role for Leads. | C34: The Hierarchy scope wins over Team (higher precedence).
A35: G. EDIT vs VIEW at record level
A36: 28 | B36: Give U9 'View = All' but 'Edit = Owned' for Leads. As U9 open a lead they do NOT own and try to edit it. | C36: U9 can open/read it but cannot save changes to a lead they do not own.
A37: 29 | B37: As that same U9, edit a lead they DO own. | C37: Allowed.
A38: H. RECORD SHARING (one-off, with expiry)
A39: 30 | B39: Share a single lead with a colleague and set an expiry a few minutes ahead. | C39: The colleague can open that one lead now.
A40: 31 | B40: After the expiry passes, the colleague opens the shared lead again. | C40: Access is gone; it can no longer be opened.
...

Sheet 4. Editing & Audit Log
A1: Sl No | B1: Action | C1: Expected Outcome | D1: Result | E1: Remarks
A2: A. EDITS PERSIST AND ARE AUDITED (do this for each record type below)
A3: 1 | B3: Edit an existing LEAD: change its name, owner and one custom field; save. | C3: The changes are saved and still show after you reload the lead.
A4: 2 | B4: Open Admin > Audit Log and find that lead edit. | C4: There is an 'update' entry naming WHO edited it and WHEN, and showing the before and after values.
A5: 3 | B5: Edit an existing CUSTOMER (e.g. status, SLA) and check the audit log. | C5: The change persists and an 'update' entry with before/after is recorded.
A6: 4 | B6: Edit a PRODUCT (e.g. price) and check the audit log. | C6: The change persists and is recorded with before/after.
A7: 5 | B7: Edit a PROJECT TASK (e.g. status, assignees) and check the audit log. | C7: The change persists and is recorded.
A8: 6 | B8: Edit a HELPDESK TICKET (e.g. priority, status) and check the audit log. | C8: The change persists and is recorded.
A9: 7 | B9: Edit a QUOTATION (e.g. a line item, notes) and check the audit log. | C9: The change persists and is recorded (unless money is locked — see Money Path).
A10: 8 | B10: Edit a USER and a ROLE (e.g. rename, change permissions) and check the audit log. | C10: Both changes persist and are recorded, including permission changes.
A11: B. CREATE & DELETE ARE AUDITED
A12: 9 | B12: Create a brand-new record (e.g. a lead) and check the audit log. | C12: A 'create' entry is recorded for it.
A13: 10 | B13: Delete a record (e.g. a task) and check the audit log. | C13: A 'delete' entry is recorded for it.
A14: 11 | B14: Do a BULK action (e.g. bulk status change on several leads) and check the audit log. | C14: The bulk change is recorded.
A15: C. WHAT IS AND IS NOT CAPTURED
A16: 12 | B16: Just OPEN/VIEW a record without changing anything, then check the audit log. | C16: Simply viewing is NOT logged — only creates, edits and deletes are.
A17: 13 | B17: Edit a record that contains a secret/password field (e.g. an integration setting) and open its audit entry. | C17: Any secret value is masked in the audit entry, not shown in clear text.
A18: 14 | B18: Log in and log out, then check the audit log. | C18: Login and logout are recorded as security events.
A19: D. AUDIT ACCESS & EXPORT
A20: 15 | B20: As a user WITHOUT audit permission, try to open the Audit Log. | C20: Access is blocked or the menu item is hidden.
A21: 16 | B21: As a permitted user, filter the audit log (by user, by action, by date) and export it. | C21: Filtering works and an export file downloads.

Sheet 5. Filters, Columns & Views
A1: Sl No | B1: Action | C1: Expected Outcome | D1: Result | E1: Remarks
A2: A. CREATE CUSTOM FIELDS (leads)
A3: 1 | B3: Create a custom lead field of type Text; another Number; another Date; another Checkbox (yes/no); another Dropdown with a few choices. | C3: Each field type saves and appears on the lead form.
A4: 2 | B4: Mark the Dropdown field as REQUIRED, then create a lead and leave it blank. | C4: Saving is blocked until the required field has a value.
A5: 3 | B5: On that Dropdown field, type a value that is NOT one of its choices (if possible) and save. | C5: Blocked with a message like 'must be one of: ...'.
A6: 4 | B6: In the Number custom field, type letters. In the Date custom field, type an impossible date. | C6: Bad values are blocked with clear messages; no broken data is saved.
A7: 5 | B7: Set the display ORDER of custom fields and reopen the lead form. | C7: The fields appear in the set order.
A8: 6 | B8: Try to create two custom fields with the same name/key. | C8: Blocked; the field key must be unique for that record type.
A9: 7 | B9: Turn a custom field to inactive. | C9: It stops appearing on the form for new entries.
A10: B. CUSTOM FIELDS IN LISTS, FILTERS, IMPORT/EXPORT
A11: 8 | B11: Turn ON 'show in list' for a custom field, then open the Leads list. | C11: The custom field appears as a column you can show.
A12: 9 | B12: Filter or sort the Leads list by a custom field. | C12: The list filters/sorts by the custom field value.
A13: 10 | B13: Export leads that have custom field values. | C13: The exported file includes the custom field columns and values.
A14: 11 | B14: Import leads from a file that includes a custom field column. | C14: The custom values are imported onto the leads; bad values are reported.
A15: C. CUSTOM FIELDS FLOWING INTO RULES (cross-feature)
A16: 12 | B16: Create a routing rule that uses a custom field as a condition, then create a matching lead. | C16: The lead is routed based on the custom field value.
A17: 13 | B17: Create an automation rule that reads a custom field, then DELETE that custom field. | C17: The automation is marked invalid / warned (it points to a removed field), rather than silently misbehaving. (If automations are not available, mark N/A and note it.)
A18: D. CUSTOM FIELDS ON OTHER RECORDS
A19: 14 | B19: If the app allows custom fields on records other than leads (e.g. contacts, products), create one and use it. | C19: The custom field works on that record the same way. If not available for that record, mark N/A.
A20: 15 | B20: For Products, create a product extension schema with fields and attach it to a product. | C20: The product carries the extra fields and validates them.
A21: E. PERSONAL VIEW SETTINGS (columns, sort, filters)
A22: 16 | B22: On the Leads list, change which columns are shown and their order; change the sort; save the view. | C22: Your column choice, order and sort are remembered for you after reload.
A23: 17 | B23: Log in as a DIFFERENT user and open the same Leads list. | C23: The other user sees their OWN view (or the company default), not your personal changes.
A24: 18 | B24: Set a company DEFAULT view for leads (as admin), then have a user who has not customised anything open the list. | C24: That user sees the company default view.
A25: 19 | B25: Customise a user's own view, then confirm the source shown is 'custom' vs 'default' for a fresh user. | C25: A customised user is on their own view; an untouched user falls back to the default.
A26: 20 | B26: Repeat view settings on another record type (e.g. Products or Contacts). | C26: View settings work per record type and per view (list/detail/form), independently.
A27: 21 | B27: Ask for a saved view with an invalid record type or view type (edge input). | C27: The app rejects it with a clear message listing the valid choices.
A28: F. SAVED FILTERS
A29: 22 | B29: On the Leads list, apply a few filters and Save them as a named filter. | C29: The saved filter appears as a chip/entry you can re-apply.
A30: 23 | B30: Click the saved filter later. | C30: The list re-applies exactly those filter conditions.
A31: 24 | B31: Try to save a filter with the SAME name as an existing one for the same list. | C31: Blocked with a clear 'a filter with that name already exists' message.
A32: 25 | B32: Try to Save a filter with NO conditions set. | C32: Blocked; you are asked to add at least one filter first.
A33: 26 | B33: Save filters until you reach the limit (5 per list), then try to save a 6th. | C33: The 6th is blocked with a clear 'limit of 5 reached' message.
A34: 27 | B34: Build a filter on a field, then have an admin remove/rename that field; re-open the saved filter. | C34: The saved filter is shown as invalid/needs attention rather than silently filtering wrongly.
A35: 28 | B35: Edit an existing saved filter's conditions and save. | C35: The edit is saved and re-applying uses the new conditions (editing in place is not blocked by the limit).
A36: 29 | B36: Log in as a DIFFERENT user and look for your saved filter. | C36: Saved filters are private to each user — the other user does not see yours.
A37: 30 | B37: Delete a saved filter. | C37: It is removed from your list.
A38: G. DEFAULT / SYSTEM FILTERS
A39: 31 | B39: Open a list and look at the built-in quick filters/tabs (e.g. All / My / Unassigned). | C39: The default system filters work and show the right subset.
A40: 32 | B40: Open a list fresh (no filter chosen). | C40: The list opens on its sensible default view, not an error or a random subset.
...

Sheet 6. CRM - Leads
A1: Sl No | B1: Action | C1: Expected Outcome | D1: Result | E1: Remarks
A2: A. SET UP LEAD PIPELINE
A3: 1 | B3: Create lead stages (e.g. New, Qualified, Won, Lost) each with a colour and order. | C3: Stages save with colours and order.
A4: 2 | B4: Mark one stage default, one 'converted/won', one 'lost'. Try to set a SECOND default. | C4: Only one of each is allowed; the second default is blocked.
A5: 3 | B5: Try to delete a stage that leads are using. | C5: Blocked; the stage is in use.
A6: 4 | B6: Create lead sources, lost reasons and a hierarchical territory (a zone with a sub-zone). | C6: They save and are available on the lead form.
A7: B. CREATE LEADS
A8: 5 | B8: Create a lead with full details: name, company, e-mail, phone with country code, source, owner. | C8: Saved and opens with all details correct.
A9: 6 | B9: Create a lead with only a first name. | C9: Saved; the full name is built from the first name.
A10: 7 | B10: Create a lead with NO first name at all. | C10: Saved; it gets an auto number like LEAD-00001.
A11: 8 | B11: Create many auto-named leads quickly (or two at the exact same moment). | C11: Each gets a unique number; no two leads share the same auto number.
A12: 9 | B12: Create two leads with the exact same full name. | C12: Blocked; lead names are unique within the company.
A13: 10 | B13: Enter an e-mail without '@' and a phone with letters. | C13: Bad contact values are blocked or cleaned; obviously broken details are not saved silently.
A14: 11 | B14: Type a very long description (thousands of characters) and add emoji and non-English letters. | C14: Saved and shown correctly without breaking the layout.
A15: 12 | B15: Set the 'unsubscribed' and 'do-not-disturb' flags on a lead. | C15: The flags save (outbound tools should later respect them).
A16: C. DUPLICATE DETECTION
A17: 13 | B17: Turn on duplicate detection by e-mail, then create a lead with the same e-mail as an existing one. | C17: The new lead is flagged as a possible duplicate; not silently merged or deleted.
A18: 14 | B18: Switch duplicate detection to 'phone' and repeat with a matching phone. | C18: The duplicate is detected by phone.
A19: 15 | B19: Switch to 'both' and create a lead matching only e-mail, then only phone. | C19: Either match flags a duplicate.
A20: D. LEAD SCORING (0-100)
A21: 16 | B21: Open a lead and view its score and the score breakdown. | C21: A score 0-100 with a simple breakdown is shown.
A22: 17 | B22: Add several activities/interactions to a lead, then recalculate scores. | C22: The score rises to reflect recent activity and interaction count.
A23: 18 | B23: Compare a lead touched today vs one untouched for 2 months after recalculation. | C23: The recently-touched lead scores higher (recency and consistency both reward recent activity).
A24: 19 | B24: Select many leads and use 'Recalculate scores'. | C24: All selected scores update.
A25: E. LISTS & BULK ACTIONS
A26: 20 | B26: Filter by stage, owner and source; sort by a column; search by name. | C26: The list updates correctly for each.
A27: 21 | B27: Select several leads and Bulk Assign to another owner. | C27: All move to the new owner.
A28: 22 | B28: Select several leads and Bulk Change Status. | C28: All change to the new stage.
A29: 23 | B29: Select several leads and Bulk Delete. | C29: They are removed (recoverable if soft-deleted).
A30: 24 | B30: Bulk archive lost leads (turn on auto-archive lost leads and mark some lost). | C30: Lost leads are archived as configured.
A31: 25 | B31: Select zero leads and press a bulk action. | C31: The app does nothing harmful and prompts you to select rows.
A32: 26 | B32: Page through a very large leads list. | C32: Paging is smooth (100 per page); no freeze or loading everything at once.
A33: F. CONVERSION APPROVAL (deep — see Money Path for the money side)
A34: 27 | B34: As a salesperson, raise a conversion approval request with a reason. | C34: A pending request is created.
A35: 28 | B35: As the SAME salesperson, try to approve your own request. | C35: Blocked; you cannot approve your own.
A36: 29 | B36: As a peer at the same level (not the manager), try to approve. | C36: Blocked; the approver must be above the requester in the chain.
A37: 30 | B37: As the requester's manager (or higher up the chain), approve it. | C37: Approved; the lead may convert.
A38: 31 | B38: As a grand-manager two levels up, approve a request. | C38: Approved — the whole management chain can approve, not only the direct manager.
A39: 32 | B39: Raise a second approval request for the same lead while one is pending. | C39: Blocked; only one pending request per lead.
A40: 33 | B40: Give the approver the Approve permission but remove it, then try to approve. | C40: Without Approve permission the approval is refused even for a manager.
...

Sheet 7. Capture & Routing
A1: Sl No | B1: Action | C1: Expected Outcome | D1: Result | E1: Remarks
A2: A. WEBSITE LEAD CAPTURE (WEBHOOK KEY)
A3: 1 | B3: Create a website capture key with a source, default owner and default stage. | C3: Created; only the last 4 characters of the secret are shown.
A4: 2 | B4: Set 'browser mode' with an allowed website address and submit a test lead from that address. | C4: The lead is captured and appears in the leads list with the default source/owner/stage.
A5: 3 | B5: Submit from a website address NOT on the allowed list. | C5: Rejected.
A6: 4 | B6: Set 'signed/server mode' and submit WITHOUT the correct signature. | C6: Rejected.
A7: 5 | B7: Submit the signed lead WITH the correct signature. | C7: Captured successfully.
A8: 6 | B8: Send more submissions per minute than the key's limit (default 30). | C8: Extra submissions that minute are rejected.
A9: 7 | B9: Deactivate or revoke the key and submit again. | C9: Refused because the key is off.
A10: 8 | B10: Open the capture history/log. | C10: Each attempt is listed as Accepted, Rejected or Duplicate with details.
A11: 9 | B11: Submit a lead with missing or junk fields. | C11: Handled gracefully — captures what it can or rejects with a clear log entry; no crash.
A12: 10 | B12: Submit a lead that duplicates an existing one (with duplicate detection on). | C12: It is logged as Duplicate and flagged.
A13: B. META (FACEBOOK / INSTAGRAM) LEAD ADS
A14: 11 | B14: Connect a Meta advertising account (app id, token, page) in Meta Ads settings. | C14: The connection saves and shows connected.
A15: 12 | B15: Pull leads from Meta (bulk pull) and view the staged leads. | C15: Meta leads appear in a staging list, not straight in the pipeline.
A16: 13 | B16: Promote staged Meta leads into real leads. | C16: The promoted leads appear in the normal leads list.
A17: 14 | B17: Enter a wrong token or disconnect, then pull leads. | C17: A clear connection error is shown, not a broken page.
A18: C. AUTOMATIC ROUTING (assignment rules)
A19: 15 | B19: Create a routing rule with conditions (e.g. source = Meta) and a target team, with points. | C19: The rule saves.
A20: 16 | B20: Try to save a rule with NO target team and NO target role. | C20: Blocked; a team or role is required.
A21: 17 | B21: Try to save a rule with EMPTY conditions. | C21: Blocked; conditions are required.
A22: 18 | B22: Create a lead matching the rule and check who it is assigned to. | C22: Auto-assigned to an eligible person from the matching rule.
A23: 19 | B23: Create two rules with different priorities that both match a lead. | C23: Rules are applied in priority order (lower number first); points add up as designed.
A24: 20 | B24: Create a lead that matches NO rule. | C24: The lead is left with a clear 'no match' state, not lost.
A25: 21 | B25: Turn on 'restrict to business hours' and create a lead OUTSIDE business hours. | C25: Assignment is held as 'pending' and happens when business hours resume.
A26: 22 | B26: Set two agents with equal points and send matching leads. | C26: Leads are shared fairly — fewest open leads first, then longest wait.
A27: D. ROUTING — DEEPER CORNER CASES
A28: 23 | B28: Create three rules with different priorities and overlapping conditions; create a lead matching all three. | C28: Rules apply in priority order (lower number first) and points accumulate as designed; the winner is the agent with the most points.
A29: 24 | B29: Two eligible agents end with equal points; one has fewer open leads. | C29: The agent with fewer open leads wins the tie.
A30: 25 | B30: Two eligible agents have equal points AND equal open-lead counts. | C30: The agent who has waited longest since their last lead wins (round-robin).
A31: 26 | B31: Disable a routing rule, then create a lead that only that rule matched. | C31: The disabled rule is ignored; the lead falls through to the next rule or to 'no match'.
A32: 27 | B32: Edit a rule's conditions and re-test. | C32: The new conditions take effect for new leads.
A33: 28 | B33: Create a lead outside business hours (business-hours restriction ON), then wait for hours to resume. | C33: The lead stays 'pending' and is auto-assigned within about 15 minutes of business hours resuming.
A34: E. WEBHOOK & META — EDGE CASES
A35: 29 | B35: Send the SAME signed webhook payload twice. | C35: The second is treated as a duplicate (logged as Duplicate), not a second lead.
A36: 30 | B36: Exceed the per-minute rate limit, then wait a minute and submit again. | C36: Blocked during the burst; accepted again once the minute window resets.
A37: 31 | B37: Rotate/replace a webhook key's secret and submit with the OLD signature. | C37: The old signature is refused after rotation.
A38: 32 | B38: Let a Meta page token expire (or revoke it) and let the sync run. | C38: The app records a clear connection error and does not crash; reconnecting fixes it.
A39: 33 | B39: Map a Meta form field to a CRM field, then pull a lead. | C39: The mapped value lands in the correct CRM field on the promoted lead.

Sheet 8. Money Path (Quote-Pay)
A1: Sl No | B1: Action | C1: Expected Outcome | D1: Result | E1: Remarks
A2: A. QUOTATION TEMPLATES & SETTINGS
A3: 1 | B3: Upload a quotation template (HTML with placeholders) and define its fields. | C3: The template saves and is available when creating a quotation.
A4: 2 | B4: Set the company quotation validity default (7/15/30/60/90 days) and expiry reminder settings. | C4: The settings save.
A5: 3 | B5: Set the quotation number prefix and next number (document numbering). | C5: New quotations use that prefix and sequence.
A6: B. CREATE A QUOTATION
A7: 4 | B7: Create a quotation on a lead, add several line items with quantity and unit price. | C7: Each line total (qty x price) and the grand total are calculated automatically and correctly.
A8: 5 | B8: Check the quotation number. | C8: It uses the company prefix and the next number in sequence.
A9: 6 | B9: Create a quotation WITHOUT setting a validity date. | C9: The validity date is filled automatically from the company default (e.g. today + 30 days).
A10: 7 | B10: Create two quotations at nearly the same time. | C10: They get different sequential numbers; no clash.
A11: 8 | B11: Run Render / Summary / Receipt on the quotation. | C11: The final document is produced from the template with values filled in.
A12: 9 | B12: Enter a negative quantity or a negative unit price on a line item. | C12: Blocked or handled sensibly; totals never go wrong silently.
A13: C. PAYMENT TYPE = LUMPSUM
A14: 10 | B14: Create a lumpsum quotation with a due date and accept it (move to the 'accepted/converted' status). | C14: One payment record is created for the full amount, due on the quotation due date.
A15: 11 | B15: Mark that record Paid. | C15: The payment plan shows fully paid / completed.
A16: D. PAYMENT TYPE = EVEN INSTALLMENTS (rounding matters)
A17: 12 | B17: Create an even-installment quotation for a total that does NOT divide evenly (e.g. 100 over 3) and accept it. | C17: Exactly 3 records are created; they add up to the total, with the LAST record absorbing the rounding (e.g. 33.33, 33.33, 33.34).
A18: 13 | B18: Add up all installment 'expected' amounts. | C18: The sum equals the quotation total exactly, to the last paisa/cent.
A19: 14 | B19: Check the due dates of the installments. | C19: They step forward by the billing period (default 30 days) from today.
A20: E. PAYMENT TYPE = SUBSCRIPTION (rolls forward)
A21: 15 | B21: Create a subscription quotation and accept it. | C21: Two payment records are created first (current period + next period).
A22: 16 | B22: Mark the current period's record Paid. | C22: The next period's record is created automatically — the subscription rolls forward.
A23: 17 | B23: Check that follow-up tasks were created for upcoming periods. | C23: Follow-up tasks (and calendar entries) are created for the upcoming due dates.
A24: F. PAYMENT TYPE = CUSTOM INSTALLMENTS
A25: 18 | B25: Create a custom-installment quotation and accept it. | C25: No installments are pre-created; you add them yourself.
A26: 19 | B26: Add several custom installments with different amounts and due dates. | C26: The quotation/plan total equals the sum of the custom installments.
A27: G. ACCEPTANCE AUTO-CONVERTS THE LEAD (key behaviour)
A28: 20 | B28: On a lead that is NOT yet a customer, accept its quotation. | C28: Accepting the quote automatically converts the lead into a customer AND creates the payment plan.
A29: 21 | B29: Open the new customer after acceptance. | C29: The customer carries the lead's details; the quotation(s) and notes/tasks/attachments moved onto the customer.
A30: 22 | B30: Accept a quotation on a lead whose stage is NOT set to an 'active' quotation status (edge). | C30: Behaviour is consistent with the rule that conversion needs an active quotation; no half-finished state.
A31: H. REVERTING AN ACCEPTED QUOTATION (dangerous edit)
A32: 23 | B32: Take an accepted quotation and change its status BACK to a non-accepted one (e.g. Draft). | C32: The payment plan, its records and the follow-up tasks created for it are removed cleanly.
A33: 24 | B33: Re-accept the same quotation again. | C33: A fresh payment plan is created; there is no leftover duplicate from before.
A34: I. PAYMENT RECORDS — CORNER CASES
A35: 25 | B35: On a plan with several pending records, pay enough to cover the FULL total early. | C35: The plan is marked completed and the remaining pending records (and their tasks) are cancelled automatically.
A36: 26 | B36: Enter a paid amount LARGER than the amount expected on a record. | C36: Handled sensibly (blocked or clearly shows over-payment); the plan maths stays correct.
A37: 27 | B37: Enter a paid amount smaller than expected (part payment). | C37: The remaining amount is tracked correctly; the record/plan reflects the shortfall.
A38: 28 | B38: Attach a receipt file to a payment record. | C38: The file saves against that record.
A39: 29 | B39: Check the plan's 'next due date' after paying one record. | C39: It updates to the earliest still-pending record.
A40: 30 | B40: Delete or cancel a single payment record and watch the plan totals. | C40: The plan recalculates its totals and next due date correctly.
...

Sheet 9. CRM - Records
A1: Sl No | B1: Action | C1: Expected Outcome | D1: Result | E1: Remarks
A2: A. CUSTOMERS
A3: 1 | B3: Open a customer's 360 detail page. | C3: It shows the customer's products, quotations, payments, projects and support tickets together.
A4: 2 | B4: Set the customer's service level (SLA) as a number and unit (hours/days). | C4: Saved; it is later used for that customer's support ticket deadlines.
A5: 3 | B5: Add products to a customer with quantities. | C5: Products and quantities save on the customer.
A6: 4 | B6: Use Bulk Change Status and Bulk Assign on customers. | C6: Selected customers update correctly.
A7: 5 | B7: Set a customer status and confirm the allowed statuses (Active / Completed / Lost / Upsell In Progress). | C7: The status saves with the right colour/label.
A8: B. CONTACTS
A9: 6 | B9: Create a contact with full details and mark it primary. | C9: Saved with the primary flag.
A10: 7 | B10: Add a second contact for the same company and mark IT primary. | C10: The primary flag behaves sensibly (only the intended one stays primary).
A11: C. PRODUCTS
A12: 8 | B12: Create a product with name, code, price and currency. | C12: Saved.
A13: 9 | B13: Try to create another product with the SAME code. | C13: Blocked; codes are unique.
A14: 10 | B14: Try to create another product with the same NAME in different letter case (e.g. 'Plan A' vs 'plan a'). | C14: Blocked; treated as the same name.
A15: 11 | B15: Enter a price with many decimals and a large value. | C15: Saved and shown correctly, not rounded away or overflowed.
A16: 12 | B16: Bulk Activate / Deactivate / Delete products. | C16: Selected products update correctly.
A17: 13 | B17: Open a product's 'usage' view before deleting. | C17: It shows where the product is used.
A18: 14 | B18: Try to delete a product TYPE that products use. | C18: Blocked; the type is in use.
A19: D. TASKS & FOLLOW-UPS
A20: 15 | B20: Create one task of each type (Task, Call, Meeting, Email, Deadline) with a due date/time. | C20: Each saves with its type and priority.
A21: 16 | B21: Add a reminder (e.g. 1 hour before) with a near due time. | C21: The reminder is saved; the tester can later confirm the reminder notification appears.
A22: 17 | B22: Mark a task complete, then try to reopen it. | C22: Completion works; reopen behaves exactly as the task settings allow.
A23: 18 | B23: Create a follow-up and view Today / Overdue / Upcoming. | C23: It appears in the correct list by date.
A24: 19 | B24: Set a due date/time in the PAST. | C24: Saved and shown overdue, or warned; no silent broken state.
A25: 20 | B25: Turn on 'auto-create a task when a lead is created' and create a lead. | C25: A task is created automatically for the new lead.
A26: 21 | B26: Turn on 'auto-close tasks when a deal is won' and win a deal. | C26: The related open tasks close automatically.
A27: E. NOTES
A28: 22 | B28: Add a note to a lead, give it a type and pin it. | C28: Saved; the pinned note stays on top.
A29: 23 | B29: Attach a file to a note and reopen it. | C29: The attachment saves and can be opened.
A30: F. CALLS & TELEPHONY
A31: 24 | B31: Set up Exotel telephony and an agent number. | C31: Telephony settings save.
A32: 25 | B32: Make a click-to-call from a lead (if a test line exists) and view the call log. | C32: The call is placed and a call log entry is created with direction and duration.
A33: 26 | B33: Add a note or create a task directly from a call log entry. | C33: The note/task is created and linked to the call.
A34: 27 | B34: Turn on call transcription and set scope (All / Admins / Selected users). | C34: The scope saves; transcription only applies to the chosen people.
A35: 28 | B35: After a recorded call, check transcription status and summary. | C35: Status moves Pending -> Processing -> Completed and a transcript/summary appears.
A36: G. MONTHLY GOALS (simple sales target — not the Rewards module)
A37: 29 | B37: Set a monthly goal (target number) for a user for the current month. | C37: Saved for that user and month.
A38: 30 | B38: Try a SECOND goal of the same type for the same user and month. | C38: Blocked; one goal per user/type/month.
A39: 31 | B39: Mark a goal recurring and check next month. | C39: It carries forward to next month when no new goal is set.
A40: 32 | B40: Compare achievement against target on the dashboard. | C40: Achievement is shown against target correctly.
...

Sheet 10. Project
A1: Sl No | B1: Action | C1: Expected Outcome | D1: Result | E1: Remarks
A2: A. PROJECT SETUP
A3: 1 | B3: Create project statuses and task statuses, each with a colour and order; mark flags 'closed' and 'cancelled'. | C3: They save; a 'cancelled' status must also be 'closed' (the app enforces this). | D3: Blocked | E3: statuses are seeded by default when an org is registered
A4: 2 | B4: Open project settings and set defaults (view, priority, visibility) and rules (templates, comments, dependencies, auto-close, auto-archive). | C4: All settings save. | D4: Blocked | E4: there is no project settings
A5: B. PROJECTS
A6: 3 | B6: Create a project with name, status, priority, dates, manager, members and a linked customer. | C6: Saved with all details. | D6: Pass
A7: 4 | B7: Try another active project with the SAME name. | C7: Blocked; active project name must be unique. | D7: Pass | E7: blocked during creation with error being dispalyed in the name field
A8: 5 | B8: Set a project's visibility to Private, then log in as a non-member. | C8: The non-member cannot see the private project. | D8: Fail | E8: users of the org can view the project
A9: 6 | B9: Set an expected end date in the past and leave the project open. | C9: It shows as Overdue. | D9: Pass
A10: 7 | B10: Archive a project, then create a NEW project reusing its name. | C10: The name can be reused once the old one is archived. | D10: Blocked | E10: no archive option
A11: C. PROGRESS CALCULATION
A12: 8 | B12: Set progress method to 'Task Completion' and mark some tasks complete. | C12: The percentage reflects the share of completed lowest-level tasks. | D12: Fail
A13: 9 | B13: Add sub-tasks under a parent and complete some. | C13: Only the lowest-level tasks count; the parent does not double-count. | D13: Fail | E13: Task progress is marked as 100 but project progress is not being updated
A14: 10 | B14: Cancel a task and re-check the percentage. | C14: Cancelled tasks are left out of the percentage entirely. | D14: Fail
A15: 11 | B15: Switch progress method to 'Manual' and set a number. | C15: The manual percentage stays as entered and is not auto-changed. | D15: Blocked | E15: no progress edit option
A16: D. TASKS, SUB-TASKS & MULTIPLE ASSIGNEES
A17: 12 | B17: Create a task with subject, status, priority (Low/Medium/High/Urgent) and due date. | C17: Saved. | D17: Pass
A18: 13 | B18: Add several assignees to one task and set one as the main owner. | C18: All assignees save; the main owner stays in the set. | D18: Fail | E18: doesnt support multiple assignees in the ui
A19: 14 | B19: Build a task tree: task -> sub-task -> sub-sub-task. | C19: The tree is built with correct parent/child links. | D19: Pass
A20: 15 | B20: Look at a parent task's rolled-up progress bar. | C20: It shows progress from its sub-tasks and matches the project bar's logic. | D20: Pass
A21: E. DEPENDENCIES — ERROR CHECKS
A22: 16 | B22: Make Task A depend on Task B. | C22: Saved (A is blocked by B). | D22: Pass
A23: 17 | B23: Try to make a task depend on ITSELF. | C23: Blocked with a clear message. | D23: Pass | E23: the task cannot be blocked on itself as the task in not displayed in the dorpdown
A24: 18 | B24: Try to add the SAME dependency twice. | C24: Blocked. | D24: Pass | E24: the same task is not displayed
A25: 19 | B25: Create a loop: A depends on B, B depends on A. | C25: Blocked; the loop is refused. | D25: Pass | E25: the task is not displayed
A26: 20 | B26: Try to depend on a task in another project (with cross-project OFF). | C26: Blocked; cross-project dependencies are not allowed unless enabled. | D26: Pass | E26: the cross proejct task is not being displayed
A27: 21 | B27: Turn cross-project dependencies ON in settings and retry. | C27: Now allowed within the same company. | D27: Blocked | E27: no option for that
A28: 22 | B28: Try to delete a task that another task depends on. | C28: Blocked until the dependency is removed. | D28: Pass | E28: failed with a clear error message
A29: F. COMPLETION RULES
A30: 23 | B30: Try to complete a parent task while its sub-tasks are open. | C30: Blocked; the app names the sub-tasks that are not done. | D30: Pass | E30: failed with a clear error message
A31: 24 | B31: Try to complete a task while a task it depends on is still open. | C31: Blocked; the app names the blocking task. | D31: Pass | E31: failed with a clear error message
A32: 25 | B32: Cancel a task even though its sub-tasks are open. | C32: Cancelling is allowed — not blocked by open sub-tasks. | D32: Pass
A33: G. COLLABORATION & UPDATES
A34: 26 | B34: Add a comment to a task, attach a file, and paste an image into the comment box. | C34: Comment, file and pasted image all save and show. | D34: Pass
A35: 27 | B35: Check the comment-count badge on a task in the list. | C35: The badge shows the correct comment count without opening the task. | D35: N/A | E35: there is no commnt count badge in list view but there is one in detail apge and it works
A36: 28 | B36: File a project status update as the manager. | C36: Saved; the manager/members are notified. | D36: Pass
A37: 29 | B37: Turn on 'collect progress' with a schedule and holiday dates. | C37: The reminder schedule saves; the tester can later confirm reminders arrive and skip holidays.
A38: H. BULK ACTIONS
A39: 30 | B39: Select several tasks and Bulk Assign / Change Status / Delete. | C39: Selected tasks update correctly. | D39: Blocked | E39: not implemeted
A40: 31 | B40: Bulk import projects from a file (valid + a few bad rows). | C40: Valid rows import; bad rows are reported; nothing is silently corrupted. | D40: Blocked | E40: not implemeted

Sheet 11. Helpdesk
A1: Sl No | B1: Action | C1: Expected Outcome | D1: Result | E1: Remarks
A2: A. TICKET SETUP
A3: 1 | B3: Create ticket types (each with a default priority) and statuses (mark one default, one resolved, one on-hold). | C3: They save; only one default status is allowed. | D3: Pass
A4: B. RAISE & WORK A TICKET
A5: 2 | B5: Raise a ticket for a customer (reported-for = Client) with subject, channel (Email/WhatsApp/Phone) and priority. | C5: Created with all details. | D5: Pass
A6: 3 | B6: Create a ticket of a type that has a default priority. | C6: It automatically gets that type's default priority. | D6: N/A | E6: no priority for type
A7: 4 | B7: Assign the ticket to an agent, then re-assign to a team. | C7: Assignment and re-assignment save. | D7: Fail | E7: assignment to an agent is working but no team assignment option
A8: 5 | B8: Link the ticket to a lead / customer / project. | C8: The linked record shows on the ticket. | D8: Pass
A9: 6 | B9: Add comments and attachments. | C9: They save and show in order. | D9: Pass
A10: 7 | B10: Create a parent ticket and a child ticket under it. | C10: The parent/child link is shown. | D10: Blocked | E10: only linked tasks can be created no parent/child ticekts
A11: C. SERVICE LEVEL (SLA) — THE KEY BEHAVIOUR
A12: 8 | B12: Set a customer's SLA (e.g. 4 hours), then raise a ticket for that customer. | C12: The ticket deadline is based on that customer's own SLA. | D12: Pass
A13: 9 | B13: Change the SAME customer's SLA afterwards and open the earlier ticket. | C13: The earlier ticket keeps its original deadline (the SLA was snapshotted when it was raised). | D13: Fail | E13: no edit/add option for sla
A14: 10 | B14: Move a ticket into an 'on-hold' status, wait, then move it back. | C14: The time spent on hold is added back to the deadline (the clock pauses while on hold). | D14: Pass
A15: 11 | B15: Put a ticket on hold and off hold twice. | C15: All the paused time adds up correctly across multiple holds. | D15: Pass
A16: 12 | B16: Let a ticket pass its deadline without resolving (and not on hold). | C16: It is flagged as breached and its priority is raised to High automatically.
A17: 13 | B17: Move a ticket into a 'resolved' status. | C17: The resolution date and time are set automatically. | D17: Pass | E17: recorded and resolved tickets cannot be edited
A18: 14 | B18: Re-open a resolved ticket. | C18: The re-open count goes up by one. | D18: Blocked | E18: recorded and resolved tickets cannot be edited
A19: D. BULK, LIST & DASHBOARD
A20: 15 | B20: Filter tickets by status, priority and assignee; search by subject. | C20: The list updates correctly. | D20: Pass
A21: 16 | B21: Bulk Assign / Change Status / Change Priority / Delete tickets. | C21: Selected tickets update correctly. | D21: Partial | E21: no bulk status change, piroity and deletion
A22: 17 | B22: Open the Helpdesk dashboard / boards. | C22: Shows counts by status, breached tickets and tickets needing attention. | D22: Pass
A23: E. PARENT & CHILD TICKETS
A24: 18 | B24: Create a parent ticket, then create two child tickets under it. | C24: The children show their parent; the parent lists its children. | D24: Blocked | E24: only linked tasks can be created no parent/child ticekts
A25: 19 | B25: Change a child ticket's status. | C25: The child updates; the parent reflects the change per the app's rule (e.g. a roll-up or activity note). | D25: Blocked | E25: only linked tasks can be created no parent/child ticekts
A26: 20 | B26: Try to make a ticket its own parent, or create a parent-child loop. | C26: Blocked; a ticket cannot be its own parent and loops are refused. | D26: Blocked | E26: only linked tasks can be created no parent/child ticekts
A27: 21 | B27: Resolve all child tickets, then look at the parent. | C27: The parent's state behaves consistently with its children being done (confirm the intended behaviour). | D27: Blocked | E27: only linked tasks can be created no parent/child ticekts
A28: 22 | B28: Delete a parent ticket that has children. | C28: The app handles it clearly (blocks, or detaches/rehomes the children) rather than leaving orphans or crashing. | D28: Blocked | E28: only linked tasks can be created no parent/child ticekts

Sheet 12. LMS (Training)
A1: Sl No | B1: Action | C1: Expected Outcome | D1: Result | E1: Remarks
A2: A. BUILD A COURSE (admin)
A3: 1 | B3: Create a course with title, description, thumbnail; add modules; add a video and a PDF to a module. | C3: All save in order.
A4: 2 | B4: Upload a very large video. | C4: Upload works (or shows clear progress/limit); the video plays after processing.
A5: 3 | B5: Try to save a course with no title. | C5: Blocked; title required.
A6: 4 | B6: Mark the course Sequential, Mandatory and set a deadline. | C6: The settings save.
A7: 5 | B7: Publish the course, then set it back to Draft. | C7: Publish/draft changes correctly; only published courses are visible to learners.
