Workbook

Sheet Cover
A1: CLOZR MOBILE APP
A2: UAT & System Test Checklist — Mobile Release Validation · v1
A4: TEST RUN DETAILS
A5: Tester name | C5: Device model & OS version
A6: Tester role | C6: App build / version
A7: Company / workspace | C7: Test start (date & time)
A8: Backend environment / URL | C8: Test end (date & time)
A10: RESULTS SUMMARY (fill in as you go — totals below are per sheet)
A11: Module (sheet) | B11: Total | C11: Pass | D11: Fail | E11: Blocked | F11: N/A | G11: Not Run | H11: % Passed
A12: 1. Onboarding & Login | B12: =COUNT('1. Onboarding & Login'!A3:A34) | C12: =COUNTIF('1. Onboarding & Login'!D3:D34,"Pass") | D12: =COUNTIF('1. Onboarding & Login'!D3:D34,"Fail") | E12: =COUNTIF('1. Onboarding & Login'!D3:D34,"Blocked") | F12: =COUNTIF('1. Onboarding & Login'!D3:D34,"N/A") | G12: =B12-C12-D12-E12-F12 | H12: =IFERROR(C12/B12,0)
A13: People - Members, Teams & Roles | B13: =COUNT('2. People'!A3:A31) | C13: =COUNTIF('2. People'!D3:D31,"Pass") | D13: =COUNTIF('2. People'!D3:D31,"Fail") | E13: =COUNTIF('2. People'!D3:D31,"Blocked") | F13: =COUNTIF('2. People'!D3:D31,"N/A") | G13: =B13-C13-D13-E13-F13 | H13: =IFERROR(C13/B13,0)
A14: CRM - Leads | B14: =COUNT('3. CRM - Leads'!A3:A46) | C14: =COUNTIF('3. CRM - Leads'!D3:D46,"Pass") | D14: =COUNTIF('3. CRM - Leads'!D3:D46,"Fail") | E14: =COUNTIF('3. CRM - Leads'!D3:D46,"Blocked") | F14: =COUNTIF('3. CRM - Leads'!D3:D46,"N/A") | G14: =B14-C14-D14-E14-F14 | H14: =IFERROR(C14/B14,0)
A15: CRM - Customers, Contacts & Products | B15: =COUNT('4. CRM - Customers & Products'!A3:A57) | C15: =COUNTIF('4. CRM - Customers & Products'!D3:D57,"Pass") | D15: =COUNTIF('4. CRM - Customers & Products'!D3:D57,"Fail") | E15: =COUNTIF('4. CRM - Customers & Products'!D3:D57,"Blocked") | F15: =COUNTIF('4. CRM - Customers & Products'!D3:D57,"N/A") | G15: =B15-C15-D15-E15-F15 | H15: =IFERROR(C15/B15,0)
A16: Money Path - Quotes, Payments & Invoices | B16: =COUNT('5. Money Path'!A3:A38) | C16: =COUNTIF('5. Money Path'!D3:D38,"Pass") | D16: =COUNTIF('5. Money Path'!D3:D38,"Fail") | E16: =COUNTIF('5. Money Path'!D3:D38,"Blocked") | F16: =COUNTIF('5. Money Path'!D3:D38,"N/A") | G16: =B16-C16-D16-E16-F16 | H16: =IFERROR(C16/B16,0)
A17: Tasks, Follow-ups, Notes, Calls & Helpdesk | B17: =COUNT('6. Tasks & Helpdesk'!A3:A53) | C17: =COUNTIF('6. Tasks & Helpdesk'!D3:D53,"Pass") | D17: =COUNTIF('6. Tasks & Helpdesk'!D3:D53,"Fail") | E17: =COUNTIF('6. Tasks & Helpdesk'!D3:D53,"Blocked") | F17: =COUNTIF('6. Tasks & Helpdesk'!D3:D53,"N/A") | G17: =B17-C17-D17-E17-F17 | H17: =IFERROR(C17/B17,0)
A18: Projects & Operations | B18: =COUNT('7. Projects & Operations'!A3:A40) | C18: =COUNTIF('7. Projects & Operations'!D3:D40,"Pass") | D18: =COUNTIF('7. Projects & Operations'!D3:D40,"Fail") | E18: =COUNTIF('7. Projects & Operations'!D3:D40,"Blocked") | F18: =COUNTIF('7. Projects & Operations'!D3:D40,"N/A") | G18: =B18-C18-D18-E18-F18 | H18: =IFERROR(C18/B18,0)
A19: Messages - Chat & WhatsApp | B19: =COUNT('8. Messages'!A3:A31) | C19: =COUNTIF('8. Messages'!D3:D31,"Pass") | D19: =COUNTIF('8. Messages'!D3:D31,"Fail") | E19: =COUNTIF('8. Messages'!D3:D31,"Blocked") | F19: =COUNTIF('8. Messages'!D3:D31,"N/A") | G19: =B19-C19-D19-E19-F19 | H19: =IFERROR(C19/B19,0)
A20: Training (LMS) | B20: =COUNT('9. Training (LMS)'!A3:A26) | C20: =COUNTIF('9. Training (LMS)'!D3:D26,"Pass") | D20: =COUNTIF('9. Training (LMS)'!D3:D26,"Fail") | E20: =COUNTIF('9. Training (LMS)'!D3:D26,"Blocked") | F20: =COUNTIF('9. Training (LMS)'!D3:D26,"N/A") | G20: =B20-C20-D20-E20-F20 | H20: =IFERROR(C20/B20,0)
A21: Rewards | B21: =COUNT('10. Rewards'!A3:A12) | C21: =COUNTIF('10. Rewards'!D3:D12,"Pass") | D21: =COUNTIF('10. Rewards'!D3:D12,"Fail") | E21: =COUNTIF('10. Rewards'!D3:D12,"Blocked") | F21: =COUNTIF('10. Rewards'!D3:D12,"N/A") | G21: =B21-C21-D21-E21-F21 | H21: =IFERROR(C21/B21,0)
A22: Dashboard & Reports | B22: =COUNT('11. Dashboard & Reports'!A3:A22) | C22: =COUNTIF('11. Dashboard & Reports'!D3:D22,"Pass") | D22: =COUNTIF('11. Dashboard & Reports'!D3:D22,"Fail") | E22: =COUNTIF('11. Dashboard & Reports'!D3:D22,"Blocked") | F22: =COUNTIF('11. Dashboard & Reports'!D3:D22,"N/A") | G22: =B22-C22-D22-E22-F22 | H22: =IFERROR(C22/B22,0)
A23: Notifications | B23: =COUNT('12. Notifications'!A3:A13) | C23: =COUNTIF('12. Notifications'!D3:D13,"Pass") | D23: =COUNTIF('12. Notifications'!D3:D13,"Fail") | E23: =COUNTIF('12. Notifications'!D3:D13,"Blocked") | F23: =COUNTIF('12. Notifications'!D3:D13,"N/A") | G23: =B23-C23-D23-E23-F23 | H23: =IFERROR(C23/B23,0)
A24: Misc (Cross-Module, Mobile) | B24: =COUNT('13. Misc (Cross-Module)'!A3:A28) | C24: =COUNTIF('13. Misc (Cross-Module)'!D3:D28,"Pass") | D24: =COUNTIF('13. Misc (Cross-Module)'!D3:D28,"Fail") | E24: =COUNTIF('13. Misc (Cross-Module)'!D3:D28,"Blocked") | F24: =COUNTIF('13. Misc (Cross-Module)'!D3:D28,"N/A") | G24: =B24-C24-D24-E24-F24 | H24: =IFERROR(C24/B24,0)
A25: GRAND TOTAL | B25: =SUM(B12:B24) | C25: =SUM(C12:C24) | D25: =SUM(D12:D24) | E25: =SUM(E12:E24) | F25: =SUM(F12:F24) | G25: =SUM(G12:G24) | H25: =IFERROR(C25/B25,0)
A27: Overall release verdict | B27: Go / No-Go
A28: Signed off by / date
A30: Notes / blockers:

Sheet How to Use
A2: How to use this checklist
B4: This workbook checks that the Clozr MOBILE app (the Flutter phone app, not the web app) works before it goes live. You do not need any technical knowledge. Just do what each row says on your phone and mark what happened.
B6: About this workbook
B7: This checklist covers only what the mobile app actually does today. Several things that exist on the Clozr web app — for example: company sign-up, custom role/permission builders that fully persist, hierarchical territory management, duplicate-lead detection, Meta Ads / webhook capture, Automations, a real course builder with quizzes, a Goals & Rewards admin console, data export/import, and multi-session security settings — are NOT available on mobile in this build, or are shown read-only. Where that's the case, a row says so plainly (often in a section called 'Not available on mobile') instead of describing a feature that doesn't exist. If you find the app now DOES do one of these things, that's good news — just mark it Pass and note it.
B9: The tabs at the bottom
B10: • Cover — fill in your name and details at the top. Fill in the results table as you finish each sheet.
B11: • How to Use — this page.
B12: • One tab per area of the mobile app: Onboarding & Login, People, CRM (Leads / Customers & Products / Money Path), Tasks & Helpdesk, Projects & Operations, Messages, Training, Rewards, Dashboard & Reports, Notifications.
B13: • The last tab, 'Misc', covers things that affect the whole app: navigation, offline behaviour, file uploads, odd input, and data separation between companies.
B14: Each test row has five columns
B15: • Sl No — the row number.
B16: • Action — what YOU should do on the phone (tap, swipe, pull to refresh, open a bottom sheet, etc.).
B17: • Expected Outcome — what SHOULD happen if the app is working correctly.
... B33: • You should never see a raw technical error, a blank white screen, or a loading spinner that never stops. If you do, note it as a Fail with the screen name.

Sheet 1. Onboarding & Login
A1: 1. Onboarding & Login
A2: Sl No | B2: Action | C2: Expected Outcome | D2: Result | E2: Remarks / Notes
B3: A. SIGN IN
A4: 1 | B4: Open the app for the first time (or after signing out) and check the sign-in screen. | C4: A 'Sign in to your workspace' screen shows Work email and Password fields and a Sign in button. No sign-up / create-company option is offered. | E4: Company/workspace creation is a web-only flow. On mobile you sign in to an existing workspace only.
A5: 2 | B5: Leave email and password blank and tap Sign in. | C5: Blocked with 'Enter your email and password.' — no request is sent.
A6: 3 | B6: Enter a badly formed email (e.g. 'john@') with any password and tap Sign in. | C6: Blocked with 'Enter a valid email address.'
A7: 4 | B7: Enter a correct email with the wrong password. | C7: Refused with 'Incorrect email or password.' — the message does not say whether the email exists.
A8: 5 | B8: Enter the correct email and password. | C8: Signed in and taken to the Dashboard (or straight to the 2FA step if the account/org requires it).
A9: 6 | B9: Tap the eye icon on the password field. | C9: Password visibility toggles between hidden and shown.
A10: 7 | B10: Tick 'Remember my email', sign in, then sign out and reopen the app. | C10: The email field is pre-filled on the next sign-in. The password is never remembered or pre-filled.
A11: 8 | B11: Untick 'Remember my email' on a device where an email was previously remembered, then sign in and reopen the app. | C11: The email field is now empty — the previously remembered address was cleared.
A12: 9 | B12: Turn off the device's internet connection and try to sign in. | C12: A clear 'you're offline' style message is shown, not a raw error or frozen spinner.
B13: B. TWO-FACTOR LOGIN (2FA)
A14: 10 | B14: Sign in on an account that already has 2FA enrolled. | C14: After the password, a 'Two-factor verification' screen asks for a 6-digit authenticator code (or a backup code).
A15: 11 | B15: On the code screen, enter a wrong 6-digit code. | C15: The code is refused and you are not let in; you can try again.
A16: 12 | B16: Leave the code box blank and tap Verify. | C16: Blocked with 'Enter the 6-digit code.'
A17: 13 | B17: Enter the correct code from the authenticator app. | C17: Signed in successfully.
A18: 14 | B18: On the code screen, tap 'Back to sign in'. | C18: Returns to the credentials screen; any error/code is cleared.
A19: 15 | B19: Sign in with a backup code instead of the authenticator code. | C19: A valid backup code is accepted the same as a normal code.
A20: 16 | B20: Sign in on an account whose organisation requires 2FA but has not enrolled yet. | C20: A 'Set up two-factor authentication' screen appears with a secret key to add to an authenticator app, and a box for the first code.
A21: 17 | B21: Complete enrolment by entering the first code from the authenticator app. | C21: Enrolment succeeds; if the response includes backup codes, a 'Save your backup codes' screen is shown before entering the app.
A22: 18 | B22: On the backup-codes screen, tap "I've saved these — continue" without writing them down. | C22: The app proceeds into the workspace; the codes are shown only once and cannot be viewed again from this screen.
B23: C. SESSION & LOGOUT
A24: 19 | B24: Sign in, fully close the app (swipe away from recents), then reopen it. | C24: You land back in the app already signed in — no need to log in again while the session is valid.
A25: 20 | B25: Stay signed in and use the app normally for an extended period. | C25: You are not thrown out mid-work; the session refreshes quietly in the background.
A26: 21 | B26: Have an admin deactivate your user account (or revoke your session) on the web app while you're signed in on mobile, then perform any action. | C26: The next server request fails with a session-expired response and the app signs you out to the login screen — your cached data for the old company does not linger.
A27: 22 | B27: Open the side drawer and check the profile footer. | C27: Your name, role and avatar (or initials if no photo) are shown.
A28: 23 | B28: Tap the gear/settings icon in the drawer footer. | C28: A 'Settings — coming soon' message appears; no settings screen opens. | E28: Confirmed placeholder in the current build — settings/company profile/branding are web-only for now.
A29: 24 | B29: Tap Sign out. | C29: You are returned to the sign-in screen; going back does not show any previous in-app screen or data.
A30: 25 | B30: Sign out, then sign back in as a DIFFERENT user in a different company. | C30: None of the previous company's leads/customers/tickets/etc. are visible or cached — the new sign-in starts clean.
B31: D. MENU & MODULE ACCESS
A32: 26 | B32: Sign in and open the side drawer/menu. | C32: It lists the modules your role and plan allow (CRM, Operations, Helpdesk, Training, Rewards, Dashboard, etc.) — it is never blank or empty.
A33: 27 | B33: Compare the drawer for an admin-type user vs. a limited-role user (two different test accounts). | C33: The limited user sees fewer modules/menu rows than the admin; each only what their role permits.
A34: 28 | B34: As a limited user, look for a module your role should not have (e.g. Billing or People) in the menu and the bottom nav. | C34: It is not shown as an option anywhere in the app for that user.

Sheet 2. People
A1: People - Members, Teams & Roles
A2: Sl No | B2: Action | C2: Expected Outcome | D2: Result | E2: Remarks / Notes
B3: A. MEMBERS LIST
A4: 1 | B4: Open the Members tab and pull to refresh. | C4: Everyone with access to the workspace loads (name, email, role, status).
A5: 2 | B5: Search members by name, email or team. | C5: The list filters live as you type.
A6: 3 | B6: Tap through the role tabs (All + each org role) above the list. | C6: The list narrows to that role and the tab's count is correct.
A7: 4 | B7: Open the filter (slider) icon, set a filter and save it as a named view. | C7: The filter applies and the view appears as a chip you can re-apply or clear.
B8: B. INVITE & EDIT A MEMBER
A9: 5 | B9: Tap Invite member, fill in a full name and a valid email, leave phone blank, and send. | C9: The invite is created and the member list refreshes to include them.
A10: 6 | B10: On the invite sheet, type a half-finished phone number (e.g. 5 digits) and try to send. | C10: Blocked with 'Enter 10 digits'; a blank phone is still allowed.
A11: 7 | B11: Invite a member and also pick a Team on the sheet before sending. | C11: The invite is sent, but a second toast explains the team could not be set from here and must be added from the team's own page. | E11: Verified in invite_member_sheet.dart: the create-member call has no team field at all — the picked team is never sent.
A12: 8 | B12: Open a member's detail screen. | C12: Profile, Member information, Performance & records and Activity log cards all load.
A13: 9 | B13: On that member's overflow menu, tap Edit member for a normal (non-admin) member. | C13: The Edit member sheet opens with their current details prefilled.
A14: 10 | B14: Open a PROTECTED account (e.g. the account that first registered the company) and check the overflow menu. | C14: Edit member is disabled/greyed out with a 'This account is protected' note, rather than opening a form the server will reject.
A15: 11 | B15: Edit a member's name, role and reporting manager, then save. | C15: Only the fields you actually changed are sent; the list and detail screen show the new values.
A16: 12 | B16: Try to save an email address already used by a different member. | C16: Blocked with the server's duplicate-email message.
A17: 13 | B17: On the Performance & records card, switch the date-range chip. | C17: The owned-lead figures (open/closed/won/value/conversion rate) re-query for the chosen range.
A18: 14 | B18: Scroll to the Availability card on a member's profile. | C18: The card is clearly captioned 'Attendance & leave tracking is coming soon' over a blurred grid. | E18: Verified in member_detail_screen.dart: the heatmap squares are generated from a hash of the member's email — not real attendance data — which is why the card is intentionally blurred and captioned rather than presented as live.
B19: C. TEAMS
A20: 15 | B20: Open the Teams tab. | C20: Groups of members load with member-count avatar stacks.
A21: 16 | B21: Tap Create team, enter a unique name, optional region/function, a lead and starting members. | C21: The team is created and appears in the list.
A22: 17 | B22: Try to create a second team with the exact same name. | C22: Blocked with a duplicate-name message.
A23: 18 | B23: Open an existing team, tap Edit, change its roster and lead, and save. | C23: Only the changed fields are sent (name / description / lead / roster); the card's member count and avatars update.
A24: 19 | B24: From a team card, tap Add and add one or more people not already on the team. | C24: The people are added and the roster refreshes, even if the picker only offers people not already on the team.
A25: 20 | B25: Read the 'Teams are for grouping only' banner on the Teams screen and the 'Team lead is a designation only' hint on Create/Edit team. | C25: Both confirm a team and its lead carry no visibility/permission scope of their own on this app. | E25: Confirmed by teams_screen.dart's own info banner and the create/edit team sheets — unlike the web app's Team-scope role visibility, a mobile team is a pure grouping label.
B26: D. ROLES & PERMISSIONS
A27: 21 | B27: Open Roles & permissions. | C27: The predefined roles (System Admin, Executive Leadership, Manager, Sales executive, Viewer) load, each marked locked.
A28: 22 | B28: Tap a predefined (locked) role card. | C28: It opens read-only with Save greyed out — you can see its scope and capabilities but not change them.
A29: 23 | B29: Tap Add role, name it, pick a Visibility scope chip and tick one or more Capability groups, then Create. | C29: A new custom role is created with EXACTLY the scope and capabilities you chose. | E29: KNOWN ISSUE, verified in add_role_sheet.dart: neither the chosen scope chip nor the ticked capability groups are sent in the create/update call — every custom role is currently created with a fixed CRM-at-hierarchy scope regardless of what the sheet shows selected. Mark this row FAIL and note the mismatch between what the sheet displays and what is actually saved.
A30: 24 | B30: Try to delete a role that still has members assigned to it. | C30: Blocked with a message naming how many members must be reassigned first.
A31: 25 | B31: Delete an unused custom role. | C31: It is removed from the list.

Sheet 3. CRM - Leads
A1: CRM - Leads
A2: Sl No | B2: Action | C2: Expected Outcome | D2: Result | E2: Remarks / Notes
B3: A. LEAD LIST & PIPELINE
A4: 1 | B4: Open the Leads tab. | C4: The list loads with stage tabs (e.g. New, Qualified, Won) each showing its own count.
A5: 2 | B5: Tap a stage tab. | C5: The list filters to leads in that stage only.
A6: 3 | B6: Pull down on the list to refresh. | C6: The leads, stage counts and filter option lists all reload from the server.
A7: 4 | B7: Tap the search icon and type part of a name, company or product. | C7: The list narrows to matching leads as you type; clearing the search restores the full list.
A8: 5 | B8: Toggle the 'My leads' / 'All leads' chip. | C8: The list switches between leads you own or are assigned and every lead you're allowed to see.
A9: 6 | B9: Search or filter down to zero results. | C9: A friendly 'No leads found' message appears with an Add lead button — never a blank or broken screen.
B10: B. ADD & EDIT A LEAD
A11: 7 | B11: Tap + to add a lead, leave Name and Phone blank, and tap Add lead. | C11: Blocked with a message to complete the required fields; name is marked required and the phone box shows 'Enter 10 digits'. | E11: Applies to the built-in form. When the company has its own configured lead fields, required-field checking is done by the server and a field-specific error comes back instead.
A12: 8 | B12: Enter a phone number with fewer than 10 digits. | C12: Blocked — the phone box shows 'Enter 10 digits' until a complete number is typed.
A13: 9 | B13: Fill in name, phone and product/need (plus any optional fields) and tap Add lead. | C13: The lead saves and appears in the leads list.
A14: 10 | B14: Open an existing lead, use the overflow menu's 'Edit lead'. | C14: The same form opens, prefilled with the lead's current details.
A15: 11 | B15: Change a field on the edit form and tap Save changes. | C15: The update saves and shows immediately on the lead's detail screen.
A16: 12 | B16: On a lead already marked Won, try Edit lead from the menu or the sticky-bar pencil. | C16: Edit is disabled/blocked with a message that the lead has converted and to edit the customer record instead.
A17: 13 | B17: On the lead's Information card, long-press an editable field. | C17: An inline edit box opens for just that field, and saving it updates the lead without opening the full edit form.
A18: 14 | B18: Long-press a read-only field such as Created on or Lead score. | C18: Nothing happens — the field is not editable inline.
B19: C. ORG-CONFIGURED FIELDS (CUSTOM SCHEMA)
A20: 15 | B20: With the company's own lead field layout configured, open Add lead. | C20: The form shows exactly the org's own fields, in the org's order and labels, in place of the built-in Contact/Deal/Qualification groups.
A21: 16 | B21: Open an existing lead's Information card under the same configured layout. | C21: The fields and their order match the org's configured detail layout rather than the built-in list.
A22: 17 | B22: As admin, remove a custom field the app previously showed, then reopen a lead that used it. | C22: The removed field's row is no longer shown; nothing breaks or shows a stale value.
B23: D. LEAD SCORE (VIEW ONLY)
A24: 18 | B24: Open a lead's detail screen. | C24: A Lead score card shows a 0-100 number, a coloured progress bar, and an 'AI summary' area marked SOON.
A25: 19 | B25: Tap the info icon beside 'Lead score'. | C25: A short explanation expands/collapses under the score. | E25: Mobile shows only the overall number and this generic note — there is no breakdown by recency, interactions, deal value etc. like the web app, and no 'recalculate score' action anywhere in the app.
A26: 20 | B26: In the filter drawer, filter leads by score (Hot / Warm / Cold). | C26: The list narrows to leads whose score falls in the chosen band.
B27: E. FILTERS & SAVED VIEWS
A28: 21 | B28: Open the filter drawer and set a mix of Source, Product, Stage, Aging-in-stage, Owner, Team, Created-date and Deal-value filters. | C28: A live 'matching' preview count updates as each filter changes.
A29: 22 | B29: Tap Apply. | C29: The list re-fetches with those filters, and a badge on the filter icon shows how many filters are active.
A30: 23 | B30: Save the current filters as a named view. | C30: It appears as a tappable chip above the list that reapplies the same filters later.
A31: 24 | B31: Try to save a view with a name that already exists, or beyond the company's saved-view limit. | C31: Blocked with the server's own message (duplicate name, or limit reached).
A32: 25 | B32: Tap an already-active saved-view chip a second time. | C32: The view deactivates and the filters clear back to the unfiltered list.
A33: 26 | B33: Open a saved view that points at a custom field the org has since deleted. | C33: The chip is shown as invalid/needing attention and refuses to run, rather than silently filtering wrong.
A34: 27 | B34: Log out and log in as a different user, then check the saved-view chips. | C34: You see that user's own saved views, not the previous user's.
B35: F. CALLING & WHATSAPP FROM A LEAD
A36: 28 | B36: From a lead card or its detail screen, tap Call. | C36: The device dialler (or the in-app calling flow, where telephony is connected) opens, and the call appears afterwards in the lead's Call log tab.
A37: 29 | B37: From the lead's overflow menu, tap 'WhatsApp chat' on a lead that already has a WhatsApp conversation in the app. | C37: The in-app chat screen opens directly on that existing thread.
A38: 30 | B38: Tap 'WhatsApp chat' on a lead with a phone number but no existing conversation yet. | C38: The number is handed off to the WhatsApp app, pre-addressed, since a first outbound WhatsApp message cannot be started from inside this screen.
A39: 31 | B39: Tap 'WhatsApp chat' on a lead with no phone number saved. | C39: A clear message says there is no number to message — nothing crashes or opens blank.
A40: 32 | B40: Turn off the connection (airplane mode) and tap 'WhatsApp chat'. | C40: The app still lets you try WhatsApp on the number, with a note that it couldn't check for an existing chat, rather than failing silently.
...

Sheet 4. CRM - Customers & Products
A1: CRM - Customers, Contacts & Products
A2: Sl No | B2: Action | C2: Expected Outcome | D2: Result | E2: Remarks / Notes
B3: A. CUSTOMERS LIST
A4: 1 | B4: Open Customers from the CRM tab. | C4: The list loads with customer cards (name, company, deal value, status pill, last activity). A loading skeleton shows briefly first.
A5: 2 | B5: Pull down on the Customers list to refresh. | C5: The list, its filter catalog and any open detail screen re-fetch and update.
A6: 3 | B6: Search customers by name and filter by status, source, account manager, company and product using the filter drawer. | C6: The list narrows to matching customers; a filter badge shows how many are applied.
A7: 4 | B7: Save the current filter combination as a view, then apply it again later. | C7: The saved view is stored on the server and re-applies the same conditions. | E7: Saved views are per-user, same as Leads.
A8: 5 | B8: Open a customer with no logo/extra data (a sparse record). | C8: Missing fields show a clean placeholder (dash), not a blank crash.
A9: 6 | B9: Look for a way to bulk-select several customers and bulk change their status or owner. | C9: n/a | E9: NOT AVAILABLE — no bulk select/action exists on the mobile Customers list (web-only feature); mark N/A.
B10: B. CREATE A CUSTOMER
A11: 7 | B11: Tap + to add a new customer and fill in name only, then save. | C11: Blocked with 'Enter a customer name' until a name is typed; once filled, the customer is created and appears at the top of the list.
A12: 8 | B12: Fill in company, mobile, email and deal value on a workspace with no custom customer layout configured, then save. | C12: The customer saves with those details; deal value shows as ₹ on the list. | E12: This 6-field built-in form only appears when the org has no configured Customer layout.
A13: 9 | B13: On a workspace WITH a configured Customer layout, open Add customer. | C13: The sheet renders the org's own fields, in the org's order and labels, instead of the built-in 6 fields.
A14: 10 | B14: On the schema-driven form, set the customer Status from the picker and save. | C14: The status is saved correctly (the app translates it to the right field internally).
A15: 11 | B15: On the schema-driven form, attach a Product to the new customer. | C15: The product is saved against the customer with a default quantity. | E15: No per-product quantity input on this form — quantity is fixed at 1; adjust via a quote if a different quantity is needed.
A16: 12 | B16: Try creating two customers with the exact same name/company in quick succession (double-tap Create). | C16: Only one customer is created — the button disables itself while the request is in flight.
A17: 13 | B17: Try to create a customer while offline or with the server rejecting the request (e.g. a required field missing). | C17: A clear error toast shows the server's message; no customer is silently created.
B18: C. CUSTOMER DETAIL
A19: 14 | B19: Open a customer's detail page. | C19: Shows the customer's overview info, status, owner, and a row of tabs: Tasks, Call log, Follow-ups, Payments, Leads, Files. | E19: There is no single '360' page combining Projects/Tickets/Quotes visually — related records live in their own tabs/sections as listed.
A20: 15 | B20: Tap the status pill and change the customer's status. | C20: The status updates immediately and the change is saved to the server.
A21: 16 | B21: Reassign the account manager (owner) from the overflow menu. | C21: The picker lists teammates from the org roster; picking one updates the owner.
A22: 17 | B22: Open the Payments tab. | C22: Shows the invoice/payment history recorded against this customer.
A23: 18 | B23: Open the Leads tab. | C23: Shows any upsell leads raised against this customer.
A24: 19 | B24: From the overflow menu, tap 'Create upsell lead' and confirm. | C24: A confirmation dialog appears; confirming creates a new lead and moves the customer to 'Upsell in progress' status, then opens the new lead.
A25: 20 | B25: Tap 'Create upsell' twice quickly. | C25: Only one upsell lead is created — the action disables itself while in flight.
A26: 21 | B26: Open the Files tab and upload an attachment. | C26: The file uploads and appears in the list; progress shows on the tab button while uploading.
A27: 22 | B27: Look for an SLA (service-level) field on the customer. | C27: n/a | E27: NOT FOUND in mobile — no SLA hours/days field on Customer; helpdesk ticket SLA (if present) is not sourced from a customer-level SLA setting here.
A28: 23 | B28: Look for a way to view/add a SECOND contact person (with a primary-contact flag) on the customer. | C28: n/a | E28: NOT AVAILABLE — mobile only carries one set of contact details (name/phone/email) per customer, same as a lead; there is no separate Contacts model.
A29: 24 | B29: Add a note to the customer and pin it. | C29: The note saves and stays pinned at the top of the thread.
A30: 25 | B30: Open the Audit / activity trail on a customer after editing it. | C30: The edit shows as an entry with who changed it and when.
B31: D. EDIT A CUSTOMER
A32: 26 | B32: Open Edit customer from the detail screen. | C32: The org's configured editable fields load pre-filled with the customer's current values.
A33: 27 | B33: On a workspace with no configured customer fields, open Edit customer. | C33: A message says the workspace has not configured any editable customer fields yet, instead of a blank or broken form.
A34: 28 | B34: Change a field and tap Save changes. | C34: The change saves, the detail page reflects it immediately, and the list updates too.
A35: 29 | B35: Tap Save changes without changing anything. | C35: A 'Nothing to save' message shows; no needless request is sent.
A36: 30 | B36: Tap Cancel after making changes. | C36: You return to the detail screen with no changes saved.
B37: E. PRODUCTS & PACKAGES — LIST
A38: 31 | B38: Open Products from the CRM tab and switch between the Products and Packages tabs/modes. | C38: Each mode shows only items of that type; counts update per mode.
A39: 32 | B39: Search and filter the product list (by category, status, etc.) and pull to refresh. | C39: The list narrows correctly and refreshes cleanly.
A40: 33 | B40: Look for bulk Activate / Deactivate / Delete on multiple selected products. | C40: n/a | E40: NOT AVAILABLE — no multi-select/bulk actions found on the mobile Products list; each item is acted on individually from its own detail page.
...

Sheet 5. Money Path
A1: Money Path - Quotes, Payments & Invoices
A2: Sl No | B2: Action | C2: Expected Outcome | D2: Result | E2: Remarks / Notes
B3: A. QUOTES — LIST & CREATE
A4: 1 | B4: Open Quotes and check the status tabs (the org's own quote statuses, or the built-in Draft/Sent/Accepted/Rejected/Expired if none are set up). | C4: Each tab shows the right count for its status.
A5: 2 | B5: Tap Add quote, pick a lead, then add two product lines with different quantities. | C5: The unit price comes from the product catalog for each line, and the line total and quote total recompute live as you change quantity.
A6: 3 | B6: Try to create a quote without picking a lead. | C6: Blocked with "Pick a lead first" — nothing is submitted.
A7: 4 | B7: Try to create a quote with no product lines added. | C7: Blocked with "Add at least one product line".
A8: 5 | B8: Choose payment type "Installments – even split" and leave the installment count blank or set it to 1. | C8: Blocked with a message that an even split needs at least 2 installments.
A9: 6 | B9: Select each payment type in turn: Lump sum, Subscription, Installments – even split, Installments – custom amounts. | C9: Each is selectable; the installment-count box only appears for even split, and the billing-period box only appears for Subscription.
A10: 7 | B10: Submit a fully filled-in quote. | C10: A confirmation toast names the new quote number and the Quotes list refreshes to include it.
A11: 8 | B11: Tap "Create quote" twice quickly (double-tap). | C11: Only one quote is created — the button disables itself while the request is in flight.
A12: 9 | B12: Search the Quotes list, apply a filter, and save it as a named view. | C12: The list updates live to match; the saved view appears as a chip you can re-apply on a later visit.
B13: B. QUOTE DETAIL & STATUS ACTIONS
A14: 10 | B14: Open a Draft or Sent quote and tap "Accept & invoice". | C14: The quote moves to the org's converted status and a toast confirms it. Note: the app does not build the invoice itself — the invoice and its payment schedule are created by the server as a side effect of this one status change.
A15: 11 | B15: On a different Sent quote, tap the reject (X) button instead of accepting. | C15: The quote moves to the org's rejected status; the Accept/Reject buttons disappear once a quote is no longer Draft or Sent.
A16: 12 | B16: Compare the total shown while building a quote on the New Quote screen against the total shown when you open that same quote's detail page. | C16: VERIFY — the New Quote screen labels its total "Tax-free — product amounts only", but the quote detail screen's line-items card adds an 18% GST line on top of the subtotal. Check which figure actually matches the amount saved on the server and flag the mismatch if the two disagree. | E16: Confirmed in code: add_quote_screen shows a tax-free total; quote_detail_screen always computes subtotal × 1.18 as TOTAL regardless of the real record. Likely a leftover mock display rather than a real tax calculation — needs a tester to confirm against the actual saved total.
A17: 13 | B17: Long-press an editable row in the "Quote details" card (e.g. valid until, notes) and change its value. | C17: The field saves through the API, and the Activity card below records the change; a row that cannot be edited explains why instead of doing nothing silently.
A18: 14 | B18: Add an internal note to a quote. | C18: The note posts and appears in the notes thread immediately.
A19: 15 | B19: Open a quote's Activity card. | C19: It shows the real audit trail (created, status changes, notes) from the server; if the audit log is unavailable it falls back to a simplified timeline derived from the quote's own status rather than showing nothing.
A20: 16 | B20: Try "Accept & invoice" on an org that has no status flagged as "converted" (check with an admin first). | C20: The app refuses with "No accepted status is configured for quotes — ask an admin to set one" instead of failing silently.
B21: C. PAYMENTS — RECORD & SETTLE
A22: 17 | B22: Open Payments and switch between the Payments and Invoices mode toggle at the top. | C22: Each mode shows its own status tabs and counts; pulling to refresh reloads both modes together, not just the one on screen.
A23: 18 | B23: Use "Record payment" (the bottom-nav +) and pick an invoice that has an unpaid installment. | C23: An info banner shows that installment's amount and label before you confirm.
A24: 19 | B24: Confirm the settle action. | C24: That installment is marked paid through the API, and both the Payments and Invoices lists refresh to show it.
A25: 20 | B25: Try Record payment on an invoice where every installment is already settled. | C25: Blocked with "All installments already settled" — the sheet closes without creating anything.
A26: 21 | B26: Look for a way to record a custom / ad-hoc amount (not tied to a scheduled installment) in Record payment while connected to the live backend. | C26: VERIFY — an ad-hoc amount option only exists in the app's offline demo mode. Against the real backend, only "Settle an installment" is offered; there is currently no backend support for recording an arbitrary one-off amount from the app. | E26: Confirmed in code: the ad-hoc toggle and its amount/date/label fields are hidden whenever the live API is in use, and the submit path shows "Recording ad-hoc payments isn't available yet" as a safeguard.
A27: 22 | B27: From an Invoice's installment schedule, tap "Settle now" on an open row. | C27: That installment is marked paid via the API and both lists refresh — the same real write as the Record payment sheet's settle path.
B28: D. PAYMENT & INVOICE DETAIL
A29: 23 | B29: Open a Payment that is not yet paid and tap the "Mark as paid" button in its header card. | C29: VERIFY — this button only shows a "Payment marked as paid" toast; it does not call the API. Reload the screen afterward and confirm the status pill still shows unpaid/due. | E29: Confirmed in code: PaymentDetailScreen's header "Mark as paid" action is a bare toast with no repository call, unlike the Invoice screen's "Settle now" row and the Record payment sheet's settle path, which do write to the server. This is an inconsistency worth reporting.
A30: 24 | B30: From a Payment's Related card, tap through to its linked Customer and Invoice. | C30: Both links open the correct record; a payment on a lead that has not converted yet shows no customer link.
A31: 25 | B31: Open an Invoice and check the TOTAL / PAID / BALANCE figures at the top. | C31: These prefer the server's own summary figures over anything computed on the device, so they should match what a web user sees for the same invoice.
A32: 26 | B32: Tap "Customer" on an invoice raised against a lead that has not converted to a customer yet. | C32: A toast explains "No customer linked — its lead has not converted yet" instead of opening a broken screen.
A33: 27 | B33: Add a note to an invoice. | C33: The note attaches to the invoice's source quotation — the backend has no separate notes bucket for a payment/invoice — and appears in the thread.
B34: E. BILLING (READ-ONLY IN THE LIVE APP)
A35: 28 | B35: Open Billing while connected to the live backend. | C35: Only three real things are shown: Storage usage, Invoice & billing history, and a list of available Plans — plus a note that plan, seats and payment mandate are "managed by support — the app cannot read or change them yet." | E35: Confirmed in code: against the live API the plan header, seat/license card, mandate card and account-state card are all left out on purpose, because no subscription endpoint exists to fill them.
A36: 29 | B36: Tap an invoice row in the billing history. | C36: A toast says "This invoice has no downloadable copy yet" — there is no PDF or download in the mobile app.
A37: 30 | B37: Tap the Plans card to open the plans list. | C37: Real plan names, prices and included modules load from the server; a note at the bottom says changing plans is handled by support and cannot be done from the app.
A38: 31 | B38: Confirm there is no working "Start trial", "Set up payment mandate", "Add/remove seats", "Cancel subscription", or "Suspend/reactivate account" control anywhere in Billing on the live app. | C38: None of these actions exist against the live backend — they are web/support-only. If a button resembling one of these appears and does something, it is only the app's offline demo mode showing a toast, not a real action, and should be reported as such.

Sheet 6. Tasks & Helpdesk
A1: Tasks, Follow-ups, Notes, Calls & Helpdesk
A2: Sl No | B2: Action | C2: Expected Outcome | D2: Result | E2: Remarks / Notes
B3: A. TASKS
A4: 1 | B4: From a lead or customer, tap + and create a task with a title, type (Call/Email/Meeting/etc.), priority (Low/Medium/High) and a due date/time. | C4: The task saves and shows on the lead/customer and in the Tasks list with its type and priority chips.
A5: 2 | B5: Try to save a new task with the title left blank. | C5: Saving is blocked until a title is entered.
A6: 3 | B6: Open a task and tap 'Mark complete'. | C6: The task shows Completed; the same tap now reads 'Completed · reopen'.
A7: 4 | B7: Tap 'Completed · reopen' on a finished task. | C7: The task reopens back to its previous status.
A8: 5 | B8: Open a task and change its status from the status chip (org-defined statuses, e.g. Open/In Progress/Done). | C8: The status updates immediately and the chip colour/label changes.
A9: 6 | B9: Attach a file to a task and reopen the task later. | C9: The file is listed under the task and can be opened.
A10: 7 | B10: Filter and search the Tasks list by status, priority and owner; pull to refresh. | C10: The list narrows correctly and refresh reloads current data.
A11: 8 | B11: Try to select several tasks at once for a bulk status change or bulk delete. | C11: N/A — the mobile app has no multi-select/bulk actions on Tasks; each task is opened and changed one at a time. | E11: Confirmed: tasks_screen.dart has no selection/checkbox UI, only single-record actions.
B12: B. FOLLOW-UPS
A13: 9 | B13: Create a follow-up against a lead/customer with a company, contact, kind (Call/Email/Meeting/Site visit), date and time. | C13: It saves and appears in the Follow-ups list, bucketed as due/overdue by its date.
A14: 10 | B14: Try to save a follow-up with no date, then check its reminder note. | C14: The app shows 'Reminders need a due date' — a follow-up needs a due date before a reminder can attach to it.
A15: 11 | B15: Open a follow-up and tap Reschedule; change only the time and save. | C15: The due date/time updates on the follow-up and its list bucket (overdue/due/done) updates accordingly.
A16: 12 | B16: Try to save a reschedule with the date field cleared. | C16: Blocked — a date is required; the sheet does not accept clearing the date as a valid reschedule.
A17: 13 | B17: Mark a follow-up done from its detail screen. | C17: It moves into the Done bucket.
A18: 14 | B18: Filter the Follow-ups list by status (overdue/due/done) and by owner (mine vs all). | C18: The list updates to match the chosen filter.
B19: C. NOTES
A20: 15 | B20: Add a note to a lead or customer with some text. | C20: The note saves and appears at the top of that record's notes feed with the author and timestamp.
A21: 16 | B21: Add a note together with a photo/file attachment in the same composer. | C21: The note saves first, then the attachment uploads against it and shows once done.
A22: 17 | B22: Add a note with an attachment while offline or with a flaky connection, then check the note afterwards. | C22: The note text itself is not lost even if the attachment upload fails — the note still shows, without the failed file. | E22: Verified in code: an upload failure keeps showing the note with the attachment that was attempted, it does not roll back the note.
A23: 18 | B23: Look for a 'pin note to top' option. | C23: N/A — the mobile app has no pin/unpin action on notes; notes are ordered by recency only. | E23: No pin field found on the note entity or notes provider.
B24: D. CALLS & TELEPHONY
A25: 19 | B25: On a lead's detail screen, tap the Call button when the org HAS Exotel telephony connected and you are set up as a telephony agent. | C25: The call routes through Exotel: your own phone rings first, then bridges to the lead. The app does not use your phone's own dialler.
A26: 20 | B26: Tap Call when Exotel is off, not configured, or you are not registered as a telephony agent. | C26: The app falls back to your phone's normal dialler, prefilled with the lead's number, and shows why Exotel wasn't used.
A27: 21 | B27: Complete a call placed through the device dialler when your own profile has NO phone number saved. | C27: The call is dialled but a message explains it could not be logged, because your own number is required to log it.
A28: 22 | B28: Use 'Log a call' to manually record a call that already happened: direction (incoming/outgoing), outcome (connected/no answer/missed) and duration. | C28: A call log entry is created and shows on the lead's call history with the right outcome and duration.
A29: 23 | B29: Look for a notes/summary box on the manual 'Log a call' sheet. | C29: N/A by design — there is no notes field on manual call logging; call summaries only come from the server's own transcription and would be silently dropped if typed here.
A30: 24 | B30: Open the call history on a lead where a call was recorded and transcribed. | C30: The recording and an AI/manual summary appear once the backend has processed them.
B31: E. HELPDESK — RAISE & WORK A TICKET
A32: 25 | B32: Create a ticket with a subject, customer, channel (Phone/Email/WhatsApp/Walk-in), type and priority (Critical/High/Medium/Low). | C32: Saved with all fields; it appears in the Tickets list.
A33: 26 | B33: Try to create a ticket with no subject or no customer selected. | C33: Blocked until both required fields are filled.
A34: 27 | B34: Open a ticket and change its assignee(s) from the assignee sheet. | C34: The assignee avatars update on the summary card.
A35: 28 | B35: Look for an option to assign a ticket to a whole TEAM rather than individual agents. | C35: N/A — the mobile app only assigns tickets to individual people, not teams.
A36: 29 | B36: Open a ticket and change its status via the status chip. | C36: The status updates immediately (optimistically) and is reflected across the app.
A37: 30 | B37: Try to edit fields on a ticket that is Closed. | C37: Fields are locked with a clear 'This ticket is closed — reopen to edit' message; status stays changeable so it can be reopened.
A38: 31 | B38: From an open ticket, create a linked task. | C38: A task is created and shown under 'Linked tasks'; tapping it opens the same task in Operations.
A39: 32 | B39: Try to create a linked task on a Closed ticket. | C39: Blocked with 'Locked — reopen the ticket to create tasks'.
A40: 33 | B40: Look for a true parent-ticket / child-ticket structure (one ticket containing several sub-tickets). | C40: N/A — the mobile app (like the web app) only supports a single linked Operations task per ticket, not real parent/child tickets. | E40: Confirmed in the Ticket entity: a single taskId/linked-tasks list, no parentId or childIds.
...

Sheet 7. Projects & Operations
A1: Projects & Operations
A2: Sl No | B2: Action | C2: Expected Outcome | D2: Result | E2: Remarks / Notes
B3: A. PROJECTS LIST & CREATE
A4: 1 | B4: Open Operations > Projects and pull to refresh the list. | C4: Projects load with name, status, priority and progress bar; the list refreshes cleanly.
A5: 2 | B5: Tap + and create a project with name, type, priority, start/end dates, manager, one or more team members, a linked customer (or leave it internal), estimated cost, visibility and progress method. | C5: All thirteen fields save and show correctly when you reopen the project.
A6: 3 | B6: Create a second active project using the exact same name. | C6: The app should stop you with a clear duplicate-name message. | E6: Confirm on device — the create form does not visibly validate this client-side; it depends on the server rejecting the duplicate and the error surfacing readably.
A7: 4 | B7: Create a project and leave the customer field blank. | C7: The project saves as an internal project (no customer) rather than erroring.
A8: 5 | B8: Filter the project list and switch between the status tabs. | C8: The list narrows correctly for each filter/status.
A9: 6 | B9: Search projects by name. | C9: Matching projects appear as you type.
B10: B. PROJECT DETAIL & LIFECYCLE
A11: 7 | B11: Open a project and check the Details tab (status, priority, dates, manager, team, customer, cost, visibility, progress method). | C11: Every value set at creation is shown accurately.
A12: 8 | B12: Edit an existing project's dates, manager, assignees and cost, then save. | C12: Changes persist and show immediately on the detail screen.
A13: 9 | B13: Set a project's expected end date in the past and leave it open. | C13: The project is shown as overdue.
A14: 10 | B14: Archive a project from its menu, then check it disappears from the default list. | C14: The project is hidden from the normal list once archived; the menu now offers 'Restore project'.
A15: 11 | B15: Restore an archived project. | C15: It reappears in the normal project list.
A16: 12 | B16: Try to edit a completed or cancelled project. | C16: The project is treated as read-only/locked once completed or cancelled.
B17: C. PROGRESS CALCULATION
A18: 13 | B18: Set a project's progress method to Task-based, then complete some of its tasks. | C18: The project's progress bar climbs as tasks are completed.
A19: 14 | B19: Set a project's progress method to Manual and type a percentage. | C19: The percentage you typed is what shows — it is not silently recalculated from tasks.
A20: 15 | B20: On a Task-based project, open a task with sub-tasks and complete some sub-tasks. | C20: The task's own progress bar reflects the share of completed sub-tasks.
B21: D. TASKS & SUB-TASKS
A22: 16 | B22: Open Operations > Tasks (or a project's Tasks tab) and create a task with subject, priority, status, project, lane/group, dates and times, expected hours and weight. | C22: All fields save and appear correctly on the task detail screen.
A23: 17 | B23: Add several team members as assignees on one task (tap more than one assignee chip). | C23: All selected assignees save together on the task.
A24: 18 | B24: Open a task and add a sub-task by typing into the '+ Add subtask' box. | C24: The sub-task is added to the checklist immediately.
A25: 19 | B25: Tick a sub-task complete, then untick it. | C25: The tick state saves both ways and the done-count updates.
A26: 20 | B26: Tap into a sub-task to open its own detail screen. | C26: The sub-task detail opens correctly.
A27: 21 | B27: Try to tick the last open sub-task of a task while that task still has an unresolved dependency. | C27: The app refuses the tick with a clear message rather than silently failing.
B28: E. DEPENDENCIES
A29: 22 | B29: On a task, open Dependencies and add another task from this org as a blocker. | C29: The dependency is added and shown as a chip naming the blocking task.
A30: 23 | B30: Try to complete a task while a task it depends on is still open. | C30: Blocked, naming the blocking task.
A31: 24 | B31: Remove a dependency chip (✕). | C31: The dependency is removed and completion is no longer blocked by it.
A32: 25 | B32: Try to delete a task that another task depends on, or one with open sub-tasks. | C32: Deletion is blocked with a message to resolve sub-tasks/dependencies first.
B33: F. COLLABORATION
A34: 26 | B34: Add a comment to a task and to a project. | C34: Each comment saves and appears in that record's own thread, newest first.
A35: 27 | B35: Attach a file to a project from the Files tab. | C35: The file uploads and appears in the file list; tapping it opens the file.
A36: 28 | B36: Open a project with no files attached. | C36: A clear 'No files attached' message is shown, not a blank screen.
B37: G. GAPS VS THE WEB APP (verify on device, do not assume fixed)
A38: 29 | B38: Look for a bulk-select mode on the Projects and Tasks lists (checkboxes to bulk assign/change status/delete several at once). | C38: No bulk-action mode is offered on mobile — this is a web-only capability; each project/task is updated one at a time. | E38: Not found wired in the mobile screens; confirm on-device and log as a known parity gap rather than a bug if absent.
A39: 30 | B39: Look for an import option for projects/tasks (uploading a spreadsheet). | C39: No bulk import is offered on mobile. | E39: Web-only capability per the reference checklist; confirm absence rather than treat as a defect.
A40: 31 | B40: Look for project-level settings (task/project status builder, default view/priority/visibility rules, templates). | C40: These admin configuration screens are not part of the mobile app — project and task statuses are set up on the web/admin side and simply consumed here.

Sheet 8. Messages
A1: Messages - Chat & WhatsApp
A2: Sl No | B2: Action | C2: Expected Outcome | D2: Result | E2: Remarks / Notes
B3: A. CONVERSATION LIST
A4: 1 | B4: Open Messages. | C4: The conversation list loads: avatar with online dot, name, company, last message time, unread badge and a 24-hour window chip on each row.
A5: 2 | B5: Search conversations by name or company. | C5: The list filters live.
A6: 3 | B6: Open a conversation that shows an unread badge. | C6: It opens and the badge clears from the list.
A7: 4 | B7: Compare a conversation with an open window (green 'Xh Ym left' chip) against one with a closed window (grey 'Window closed' chip). | C7: Each chip's colour and label match that conversation's real 24-hour-window state.
B8: B. CHAT — WITHIN THE 24-HOUR WINDOW
A9: 5 | B9: Open a chat whose window is open. | C9: A free-form text composer is shown under a green 'Within 24-hour window' banner with a countdown.
A10: 6 | B10: Type and send a plain text message. | C10: It appears immediately as an outgoing bubble, then confirms as sent.
A11: 7 | B11: Send a message with the connection off (airplane mode) and restore the connection after. | C11: The bubble is marked failed and offers a Retry tap; retrying re-sends it.
B12: C. CHAT — WINDOW CLOSED (TEMPLATE-ONLY)
A13: 8 | B13: Open a chat whose 24-hour window has closed. | C13: The free-text composer is replaced by a grey 'Window closed' banner and a single 'Send a template message' button — no free text can be typed.
A14: 9 | B14: Tap 'Send a template message'. | C14: A sheet lists only APPROVED WhatsApp templates, each previewed with the contact's first name filled in.
A15: 10 | B15: Pick a template and send it. | C15: It posts as an outgoing bubble tagged as a template message and the sheet closes.
A16: 11 | B16: Open the template sheet before any templates have synced from the provider. | C16: An honest 'No approved templates' empty state is shown — never a fake canned list.
B17: D. COMPOSER AFFORDANCES & CALL
A18: 12 | B18: Tap the emoji icon in the open composer. | C18: Shows an 'Emoji picker — coming soon' toast. | E18: Placeholder only — no working emoji picker exists on mobile yet.
A19: 13 | B19: Tap the paperclip (attach) icon in the composer. | C19: Shows an 'Attach — file picker coming soon' toast. | E19: Placeholder only — sending an image or document from the chat composer is not available on mobile.
A20: 14 | B20: Tap the phone icon in a chat's header. | C20: Shows a 'Calling {name}…' toast. | E20: This does not place a real call — there is no dialer or Exotel bridge wired to the Chat header on mobile.
B21: E. MEDIAS & LINKS TABS
A22: 15 | B22: Open the Medias tab on a conversation that has shared files. | C22: Files are listed with a type icon, name and date/size.
A23: 16 | B23: Tap the download icon on a media row. | C23: Check and note whether the file actually downloads or the icon is currently decorative.
A24: 17 | B24: Open the Links tab on a conversation where a URL was pasted into a message. | C24: The link is listed with a readable host/path title.
A25: 18 | B25: Open Medias and Links on a conversation with nothing shared. | C25: A friendly empty state is shown on each tab, not a blank screen.
B26: F. WHATSAPP FROM A LEAD
A27: 19 | B27: Tap a contact's name in the Chat header when it is linked to a lead. | C27: Navigates to that lead's detail screen.
A28: 20 | B28: From a Lead's detail screen, tap WhatsApp when a thread already exists for that lead. | C28: Opens the existing in-app Chat thread directly.
A29: 21 | B29: From a Lead's detail screen, tap WhatsApp when NO thread exists yet for that lead's number. | C29: Hands the number to the external WhatsApp app (a wa.me link) instead of opening an empty in-app thread. | E29: Intentional, not a bug: the API has no 'start a conversation' endpoint reachable by a normal sales user, so the first outbound message must go through WhatsApp itself; the in-app thread appears once that message gets a reply.
A30: 22 | B30: From a Lead's detail screen with no phone number saved at all, tap WhatsApp. | C30: A clear 'no number to message' outcome — never a crash or silent no-op.
A31: 23 | B31: Force the conversation list to fail loading (e.g. airplane mode) and reopen Messages. | C31: A retry control is shown; tapping it reloads the list.

Sheet 9. Training (LMS)
A1: Training (LMS)
A2: Sl No | B2: Action | C2: Expected Outcome | D2: Result | E2: Remarks / Notes
B3: A. OVERVIEW & ALL COURSES (VIEWING)
A4: 1 | B4: Open Training. | C4: Overview loads: Total courses / Total learners / Avg. completion tiles, top 3 courses and Recent activity.
A5: 2 | B5: Tap 'View all Courses'. | C5: All Courses loads with a search box and Published/Drafts status chips that filter the list.
B6: B. COURSE BUILDER — CHECK BEFORE TRUSTING IT
A7: 3 | B7: Tap 'New course', enter a title and tap Create. | C7: The course appears as a draft on screen. | E7: KNOWN GAP, verified against lms_providers.dart: the LMS layer only ever fetches courses/records/activity — there is no create, update, publish or delete call anywhere in it. Everything the Course Builder does lives in that screen's local state only and is never sent to the backend.
A8: 4 | B8: Add a module, then tap to attach a video and a PDF resource. | C8: The module shows a video and a resource file attached. | E8: Simulated: the app just toasts 'lesson-video.mp4 attached' / 'PDF attached' — there is no real file picker or upload behind either button.
A9: 5 | B9: Toggle Sequential Modules and Mandatory course, set a deadline, and tap Publish. | C9: Toasts 'Course published' and returns to the previous screen. | E9: Confirm this does not actually persist — reopening the course list or the course fresh will not show any of this, since Publish makes no API call.
A10: 6 | B10: Open an existing course in the builder and tap 'Delete the course'. | C10: Toasts 'Course deleted' only. | E10: Nothing is actually deleted server-side — treat every Course Builder action as UI-only on this build.
B11: C. COURSE DETAIL (ADMIN VIEW)
A12: 7 | B12: Open a published course's detail screen. | C12: Enrolled / Completed / In progress / Overdue tiles, a completion-rate bar, the modules list and assigned learners with per-learner progress bars all load.
A13: 8 | B13: Tap Nudge next to a learner who has not completed the course. | C13: Shows a 'Reminder sent to {name}' toast. | E13: Confirm whether this triggers a real notification to that learner or is a local toast only.
A14: 9 | B14: Tap 'Assign course' on the course detail or Learners screen. | C14: Only shows a placeholder toast — there is no working course-assignment flow on mobile yet.
B15: D. LEARNER EXPERIENCE
A16: 10 | B16: Open My Courses as a learner. | C16: A progress header, an in-progress module carousel and a 'More courses' grid load.
A17: 11 | B17: On a Sequential course, try to open module 3 before finishing module 2. | C17: Module 3 shows locked (padlock, dimmed) and tapping it toasts 'Complete the previous module first'.
A18: 12 | B18: Open an unlocked module in the player and tap play. | C18: Progress jumps to 35%. | E18: There is no real video file streaming or scrubbing behind the player — play/pause only advances a stored percentage.
A19: 13 | B19: Tap 'Mark as Completed' on the open module. | C19: The module reaches 100% and the next module unlocks (if the course is Sequential).
A20: 14 | B20: Complete every module in a course. | C20: A certificate card appears with a 'Download certificate' button; tapping it toasts 'Certificate downloaded' with no real file produced.
A21: 15 | B21: Check a course whose deadline has already passed without being finished. | C21: It is shown with an Overdue status pill for that learner.
A22: 16 | B22: Assign a Mandatory course to yourself and leave it incomplete, then use the rest of the app. | C22: Access to the rest of the app is not affected. | E22: KNOWN GAP: 'mandatory' is stored and shown only as a '· Mandatory' label on the course — nothing in the app currently blocks access for an incomplete mandatory course, unlike the web reference's intended behaviour.
